Workbook

Sheet Instructiuni
A1: Propunere financiară – Lucrări de reparații acoperiș pav. C4, cazarma 3589 București (ADV1550471)
A3: Termen: 05.10.2026, ora 14:00 –
A4: 1. Foaia Resurse: prețurile resurselor (fără TVA) din baza de prețuri BILZI, cu sursa fiecăruia. Celulele galbene se pot modifica – oferta se recalculează.
A5: 2. Foaia Analiza: consumurile pe unitatea fiecărui articol din F3 (norme uzuale, de verificat).
A6: 3. F3: prețurile unitare pe material / manoperă / utilaj / transport rezultă din Analiza; CAM 2,25% din manoperă, cheltuieli indirecte și profit în celulele galbene.
A7: 4. C6–C9, Grafic și Anexa se completează singure; rândurile „Verificare” trebuie să fie 0.
A8: 5. Valoarea estimată: 77,677.10 lei fără TVA. Oferta peste această valoare este respinsă.
A9: Profit aplicat: 9.0% (cel mai mare pas de 0,5% cu care oferta rămâne la cel mult 97% din valoarea estimată, între 5% și 25%).

Sheet F3
A1: F3 – Lista cu cantitățile de lucrări – deviz ofertă
A2: Obiectiv: Lucrări de reparații acoperiș pav. C4, cazarma 3589 București – Beneficiar: INCDMM „Cantacuzino”
A3: Ofertant: BILZI STEEL PROFILE S.R.L., CUI 39666285, J10/757/2018, Buzău
A4: Valori în lei, fără TVA
A6: Nr. | B6: Simbol | C6: Denumire articol | D6: UM | E6: Cantitate | F6: PU material | G6: PU manoperă | H6: PU utilaj | I6: PU transport | J6: Valoare material | K6: Valoare manoperă | L6: Valoare utilaj | M6: Valoare transport | N6: Total
C7: Pavilion C4 – antemăsurătoare (Anexa 1)
A8: 1 | B8: RPCT26B1 | C8: Desfacerea învelitorilor din olane, țigle solzi sau profilate pe șipci, incl. desfacerea șipcilor doliilor | D8: mp | E8: 480 | F8: =ROUND(SUMIFS(Analiza!$J$7:$J$52,Analiza!$A$7:$A$52,$A8,Analiza!$K$7:$K$52,"Material"),2) | G8: =ROUND(SUMIFS(Analiza!$J$7:$J$52,Analiza!$A$7:$A$52,$A8,Analiza!$K$7:$K$52,"Manopera"),2) | H8: =ROUND(SUMIFS(Analiza!$J$7:$J$52,Analiza!$A$7:$A$52,$A8,Analiza!$K$7:$K$52,"Utilaj"),2) | I8: =ROUND(SUMIFS(Analiza!$J$7:$J$52,Analiza!$A$7:$A$52,$A8,Analiza!$K$7:$K$52,"Transport"),2) | J8: =ROUND($E8*F8,2) | K8: =ROUND($E8*G8,2) | L8: =ROUND($E8*H8,2) | M8: =ROUND($E8*I8,2) | N8: =SUM(J8:M8)
A9: 2 | B9: RPCI01C | C9: Învelitori din țiglă solzi sau olane, coame așezate pe șipci de lemn, inclusiv doliile, paziile, șorțurile | D9: mp | E9: 480 | F9: =ROUND(SUMIFS(Analiza!$J$7:$J$52,Analiza!$A$7:$A$52,$A9,Analiza!$K$7:$K$52,"Material"),2) | G9: =ROUND(SUMIFS(Analiza!$J$7:$J$52,Analiza!$A$7:$A$52,$A9,Analiza!$K$7:$K$52,"Manopera"),2) | H9: =ROUND(SUMIFS(Analiza!$J$7:$J$52,Analiza!$A$7:$A$52,$A9,Analiza!$K$7:$K$52,"Utilaj"),2) | I9: =ROUND(SUMIFS(Analiza!$J$7:$J$52,Analiza!$A$7:$A$52,$A9,Analiza!$K$7:$K$52,"Transport"),2) | J9: =ROUND($E9*F9,2) | K9: =ROUND($E9*G9,2) | L9: =ROUND($E9*H9,2) | M9: =ROUND($E9*I9,2) | N9: =SUM(J9:M9)
A10: 3 | B10: RPCI05XB | C10: Reparații la învelitori de țigle profilate cu țigle și coame din mortar de ciment la acoperiș fără astereală | D10: mp | E10: 65 | F10: =ROUND(SUMIFS(Analiza!$J$7:$J$52,Analiza!$A$7:$A$52,$A10,Analiza!$K$7:$K$52,"Material"),2) | G10: =ROUND(SUMIFS(Analiza!$J$7:$J$52,Analiza!$A$7:$A$52,$A10,Analiza!$K$7:$K$52,"Manopera"),2) | H10: =ROUND(SUMIFS(Analiza!$J$7:$J$52,Analiza!$A$7:$A$52,$A10,Analiza!$K$7:$K$52,"Utilaj"),2) | I10: =ROUND(SUMIFS(Analiza!$J$7:$J$52,Analiza!$A$7:$A$52,$A10,Analiza!$K$7:$K$52,"Transport"),2) | J10: =ROUND($E10*F10,2) | K10: =ROUND($E10*G10,2) | L10: =ROUND($E10*H10,2) | M10: =ROUND($E10*I10,2) | N10: =SUM(J10:M10)
A11: 4 | B11: RCSI18A | C11: Jgheaburi tablă zincată 0,5 mm, semirotunde, D=12,5 cm, exec. pe șantier, incl. colțuri/capace/ștuț racord | D11: m | E11: 70 | F11: =ROUND(SUMIFS(Analiza!$J$7:$J$52,Analiza!$A$7:$A$52,$A11,Analiza!$K$7:$K$52,"Material"),2) | G11: =ROUND(SUMIFS(Analiza!$J$7:$J$52,Analiza!$A$7:$A$52,$A11,Analiza!$K$7:$K$52,"Manopera"),2) | H11: =ROUND(SUMIFS(Analiza!$J$7:$J$52,Analiza!$A$7:$A$52,$A11,Analiza!$K$7:$K$52,"Utilaj"),2) | I11: =ROUND(SUMIFS(Analiza!$J$7:$J$52,Analiza!$A$7:$A$52,$A11,Analiza!$K$7:$K$52,"Transport"),2) | J11: =ROUND($E11*F11,2) | K11: =ROUND($E11*G11,2) | L11: =ROUND($E11*H11,2) | M11: =ROUND($E11*I11,2) | N11: =SUM(J11:M11)
A12: 5 | B12: RPDE13A | C12: Montarea panourilor de parazăpezi din metal, cu ancore | D12: buc | E12: 70 | F12: =ROUND(SUMIFS(Analiza!$J$7:$J$52,Analiza!$A$7:$A$52,$A12,Analiza!$K$7:$K$52,"Material"),2) | G12: =ROUND(SUMIFS(Analiza!$J$7:$J$52,Analiza!$A$7:$A$52,$A12,Analiza!$K$7:$K$52,"Manopera"),2) | H12: =ROUND(SUMIFS(Analiza!$J$7:$J$52,Analiza!$A$7:$A$52,$A12,Analiza!$K$7:$K$52,"Utilaj"),2) | I12: =ROUND(SUMIFS(Analiza!$J$7:$J$52,Analiza!$A$7:$A$52,$A12,Analiza!$K$7:$K$52,"Transport"),2) | J12: =ROUND($E12*F12,2) | K12: =ROUND($E12*G12,2) | L12: =ROUND($E12*H12,2) | M12: =ROUND($E12*I12,2) | N12: =SUM(J12:M12)
A13: 6 | B13: RPIZD31B | C13: Etanșarea sau fixarea protecțiilor din tablă la îmbinări sau a izolației cu inele din bandă Al 1×20 mm | D13: m | E13: 60 | F13: =ROUND(SUMIFS(Analiza!$J$7:$J$52,Analiza!$A$7:$A$52,$A13,Analiza!$K$7:$K$52,"Material"),2) | G13: =ROUND(SUMIFS(Analiza!$J$7:$J$52,Analiza!$A$7:$A$52,$A13,Analiza!$K$7:$K$52,"Manopera"),2) | H13: =ROUND(SUMIFS(Analiza!$J$7:$J$52,Analiza!$A$7:$A$52,$A13,Analiza!$K$7:$K$52,"Utilaj"),2) | I13: =ROUND(SUMIFS(Analiza!$J$7:$J$52,Analiza!$A$7:$A$52,$A13,Analiza!$K$7:$K$52,"Transport"),2) | J13: =ROUND($E13*F13,2) | K13: =ROUND($E13*G13,2) | L13: =ROUND($E13*H13,2) | M13: =ROUND($E13*I13,2) | N13: =SUM(J13:M13)
A14: 7 | B14: W1C11B1 | C14: Plasă metalică de protecție pe cadru de oțel, ușă din plasă – montare | D14: mp | E14: 64 | F14: =ROUND(SUMIFS(Analiza!$J$7:$J$52,Analiza!$A$7:$A$52,$A14,Analiza!$K$7:$K$52,"Material"),2) | G14: =ROUND(SUMIFS(Analiza!$J$7:$J$52,Analiza!$A$7:$A$52,$A14,Analiza!$K$7:$K$52,"Manopera"),2) | H14: =ROUND(SUMIFS(Analiza!$J$7:$J$52,Analiza!$A$7:$A$52,$A14,Analiza!$K$7:$K$52,"Utilaj"),2) | I14: =ROUND(SUMIFS(Analiza!$J$7:$J$52,Analiza!$A$7:$A$52,$A14,Analiza!$K$7:$K$52,"Transport"),2) | J14: =ROUND($E14*F14,2) | K14: =ROUND($E14*G14,2) | L14: =ROUND($E14*H14,2) | M14: =ROUND($E14*I14,2) | N14: =SUM(J14:M14)
A15: 8 | B15: TRB22E6B | C15: Manipulat materiale și elemente prefabricate cu macara turn, greutatea sarcinii la fiecare transport = 0,5–1 t | D15: tonă | E15: 35 | F15: =ROUND(SUMIFS(Analiza!$J$7:$J$52,Analiza!$A$7:$A$52,$A15,Analiza!$K$7:$K$52,"Material"),2) | G15: =ROUND(SUMIFS(Analiza!$J$7:$J$52,Analiza!$A$7:$A$52,$A15,Analiza!$K$7:$K$52,"Manopera"),2) | H15: =ROUND(SUMIFS(Analiza!$J$7:$J$52,Analiza!$A$7:$A$52,$A15,Analiza!$K$7:$K$52,"Utilaj"),2) | I15: =ROUND(SUMIFS(Analiza!$J$7:$J$52,Analiza!$A$7:$A$52,$A15,Analiza!$K$7:$K$52,"Transport"),2) | J15: =ROUND($E15*F15,2) | K15: =ROUND($E15*G15,2) | L15: =ROUND($E15*H15,2) | M15: =ROUND($E15*I15,2) | N15: =SUM(J15:M15)
A16: 9 | B16: CB41B1 | C16: Susțineri din schelă metalică, sarcina 1000 daN/mp, cu înălțimea de 3–6 m, la parter | D16: mp | E16: 64 | F16: =ROUND(SUMIFS(Analiza!$J$7:$J$52,Analiza!$A$7:$A$52,$A16,Analiza!$K$7:$K$52,"Material"),2) | G16: =ROUND(SUMIFS(Analiza!$J$7:$J$52,Analiza!$A$7:$A$52,$A16,Analiza!$K$7:$K$52,"Manopera"),2) | H16: =ROUND(SUMIFS(Analiza!$J$7:$J$52,Analiza!$A$7:$A$52,$A16,Analiza!$K$7:$K$52,"Utilaj"),2) | I16: =ROUND(SUMIFS(Analiza!$J$7:$J$52,Analiza!$A$7:$A$52,$A16,Analiza!$K$7:$K$52,"Transport"),2) | J16: =ROUND($E16*F16,2) | K16: =ROUND($E16*G16,2) | L16: =ROUND($E16*H16,2) | M16: =ROUND($E16*I16,2) | N16: =SUM(J16:M16)
C17: Total Pavilion C4 – antemăsurătoare (Anexa 1) | J17: =SUM(J8:J16) | K17: =SUM(K8:K16) | L17: =SUM(L8:L16) | M17: =SUM(M8:M16) | N17: =SUM(N8:N16)
C19: Total cheltuieli directe din articole | J19: =J17 | K19: =K17 | L19: =L17 | M19: =M17 | N19: =N17
C20: Contribuție asiguratorie pentru muncă (CAM, % din manoperă) | E20: 0.0225 | K20: =ROUND(K19*E20,2) | N20: =K20
C21: Total cheltuieli directe (inclusiv CAM) | N21: =N19+N20
C22: Cheltuieli indirecte (% din cheltuieli directe) | E22: 0.03 | N22: =ROUND(N21*E22,2)
C23: Profit (% din cheltuieli directe + indirecte) | E23: 0.09 | N23: =ROUND((N21+N22)*E23,2)
C24: TOTAL GENERAL (fără TVA) – se trece în formularul de ofertă | N24: =ROUND(N21+N22+N23,2)
C25: TVA | E25: 0.21 | N25: =ROUND(N24*E25,2)
C26: TOTAL GENERAL cu TVA | N26: =N24+N25
C28: Valoarea estimată de autoritatea contractantă (fără TVA) | N28: 77677.1
C29: Încadrare în valoarea estimată | N29: =IF(N24<=N28,"DA – "&TEXT(N24/N28,"0,0%")&" din valoarea estimată","NU – depășește valoarea estimată")
C31: Notă: Sursa: Antemăsurătoarea pav. C4 (Anexa 1, întocmit ing. Iulia Păunescu) din documentația anunțului ADV1550471. Specificațiile tehnice (Anexa 2) cer: termen de execuție 45 de zile calendaristice, garanție 36 de luni, vizitarea obligatorie a amplasamentului.
C33: OFERTANT,
C34: BILZI STEEL PROFILE S.R.L.
C35: Șerban Marius – administrator
C36: Semnătura și ștampila

Sheet Resurse
A1: Prețuri resurse (fără TVA)
A2: Obiectiv: Lucrări de reparații acoperiș pav. C4, cazarma 3589 București – Beneficiar: INCDMM „Cantacuzino”
A3: Ofertant: BILZI STEEL PROFILE S.R.L., CUI 39666285, J10/757/2018, Buzău
A4: Valori în lei, fără TVA
A6: Cod | B6: Denumire resursă | C6: UM | D6: Categorie | E6: Preț unitar (lei) | F6: Sursa prețului
A7: M03 | B7: Șipci 50×50 și contrașipci 30×50 rășinoase, tratate | C7: mc | D7: Material | E7: 1150 | F7: Depozite cherestea 02.10.2026: șipcă 50×50 2,69–3,10 lei/ml, contrașipcă 1,03–1,55 lei/ml → ~1.150 lei/mc
A8: M05 | B8: Cuie pentru astereală / șipci | C8: kg | D8: Material | E8: 9 | F8: Estimare (Onești) – de verificat
A9: M06 | B9: Soluție fungicidă / insecticidă pentru lemn | C9: l | D9: Material | E9: 14 | F9: Estimare – de verificat
A10: M08 | B10: Folie anticondens min. 120 g/mp | C10: mp | D10: Material | E10: 4.18 | F10: Listă Bilka / Dedeman 02.10.2026: folie anticondens 120–150 g/mp, rolă 75 mp
A11: M30 | B11: Țiglă ceramică solzi / olan (completare) | C11: buc | D11: Material | E11: 3.11 | F11: Dedeman 02.10.2026: Creaton Klassic Biber natur 104,4 lei/mp ÷ 33,6 buc/mp
A12: M31 | B12: Coamă ceramică pentru țiglă solzi (pe mp de învelitoare) | C12: buc | D12: Material | E12: 40.86 | F12: Dedeman 02.10.2026: coamă ceramică Creaton 40,86 lei/buc fără TVA
A13: M32 | B13: Sârmă zincată / cârlige de prindere țiglă | C13: kg | D13: Material | E13: 12 | F13: Estimare – de verificat
A14: M33 | B14: Mortar de ciment-var M100 (uscat, sac) | C14: kg | D14: Material | E14: 0.6 | F14: Estimare – de verificat
A15: M34 | B15: Tablă zincată 0,50 mm (desfășurată jgheab 33 cm + pierderi) | C15: mp | D15: Material | E15: 31.65 | F15: Constal 02.10.2026: tablă zincată 0,5 mm 31,65 lei/mp fără TVA
A16: M35 | B16: Cârlig jgheab zincat semirotund | C16: buc | D16: Material | E16: 6.5 | F16: Estimare – de verificat
A17: M36 | B17: Aliaj de lipit Sn-Pb LP30 | C17: kg | D17: Material | E17: 140 | F17: Estimare – de verificat
A18: M37 | B18: Accesorii jgheab (capace, colțuri, ștuț) – cotă pe ml | C18: buc | D18: Material | E18: 14 | F18: Estimare – de verificat
... A39: T02 | B39: Container moloz 7 mc (închiriere, transport și eliminare) | C39: buc | D39: Transport | E39: 1800 | F39: Reciclero 2.281 lei (7 zile, cu tratarea deșeurilor) / Moloz24 de la 400 lei – medie rotunjită

Sheet Analiza
A1: Analiza de preț pe articole – consumuri de resurse pe unitatea de măsură a articolului
A2: Obiectiv: Lucrări de reparații acoperiș pav. C4, cazarma 3589 București – Beneficiar: INCDMM „Cantacuzino”
A3: Ofertant: BILZI STEEL PROFILE S.R.L., CUI 39666285, J10/757/2018, Buzău
A4: Valori în lei, fără TVA
A6: Nr. art. | B6: Articol | C6: Cod resursă | D6: Resursă | E6: UM | F6: Consum / UM articol | G6: Cantitate articol | H6: Consum total | I6: Preț unitar resursă (lei) | J6: Valoare / UM articol | K6: Categorie | L6: Observații
A7: =F3!A8 | B7: =F3!C8 | C7: O02 | D7: =Resurse!B28 | E7: =Resurse!C28 | F7: 0.15 | G7: =F3!E8 | H7: =F7*G7 | I7: =Resurse!E28 | J7: =F7*I7 | K7: =Resurse!D28
A8: =F3!A8 | B8: =F3!C8 | C8: O03 | D8: =Resurse!B29 | E8: =Resurse!C29 | F8: 0.22 | G8: =F3!E8 | H8: =F8*G8 | I8: =Resurse!E29 | J8: =F8*I8 | K8: =Resurse!D29
A9: =F3!A8 | B9: =F3!C8 | C9: T02 | D9: =Resurse!B39 | E9: =Resurse!C39 | F9: 0.003 | G9: =F3!E8 | H9: =F9*G9 | I9: =Resurse!E39 | J9: =F9*I9 | K9: =Resurse!D39
A10: =F3!A9 | B10: =F3!C9 | C10: M30 | D10: =Resurse!B11 | E10: =Resurse!C11 | F10: 5.4 | G10: =F3!E9 | H10: =F10*G10 | I10: =Resurse!E11 | J10: =F10*I10 | K10: =Resurse!D11
A11: =F3!A9 | B11: =F3!C9 | C11: M31 | D11: =Resurse!B12 | E11: =Resurse!C12 | F11: 0.06 | G11: =F3!E9 | H11: =F11*G11 | I11: =Resurse!E12 | J11: =F11*I11 | K11: =Resurse!D12
A12: =F3!A9 | B12: =F3!C9 | C12: M03 | D12: =Resurse!B7 | E12: =Resurse!C7 | F12: 0.0065 | G12: =F3!E9 | H12: =F12*G12 | I12: =Resurse!E7 | J12: =F12*I12 | K12: =Resurse!D7
A13: =F3!A9 | B13: =F3!C9 | C13: M08 | D13: =Resurse!B10 | E13: =Resurse!C10 | F13: 0.35 | G13: =F3!E9 | H13: =F13*G13 | I13: =Resurse!E10 | J13: =F13*I13 | K13: =Resurse!D10
A14: =F3!A9 | B14: =F3!C9 | C14: M05 | D14: =Resurse!B8 | E14: =Resurse!C8 | F14: 0.12 | G14: =F3!E9 | H14: =F14*G14 | I14: =Resurse!E8 | J14: =F14*I14 | K14: =Resurse!D8
A15: =F3!A9 | B15: =F3!C9 | C15: M06 | D15: =Resurse!B9 | E15: =Resurse!C9 | F15: 0.25 | G15: =F3!E9 | H15: =F15*G15 | I15: =Resurse!E9 | J15: =F15*I15 | K15: =Resurse!D9
A16: =F3!A9 | B16: =F3!C9 | C16: M32 | D16: =Resurse!B13 | E16: =Resurse!C13 | F16: 0.1 | G16: =F3!E9 | H16: =F16*G16 | I16: =Resurse!E13 | J16: =F16*I16 | K16: =Resurse!D13
A17: =F3!A9 | B17: =F3!C9 | C17: O02 | D17: =Resurse!B28 | E17: =Resurse!C28 | F17: 0.45 | G17: =F3!E9 | H17: =F17*G17 | I17: =Resurse!E28 | J17: =F17*I17 | K17: =Resurse!D28
A18: =F3!A9 | B18: =F3!C9 | C18: O01 | D18: =Resurse!B27 | E18: =Resurse!C27 | F18: 0.1 | G18: =F3!E9 | H18: =F18*G18 | I18: =Resurse!E27 | J18: =F18*I18 | K18: =Resurse!D27
A19: =F3!A9 | B19: =F3!C9 | C19: O03 | D19: =Resurse!B29 | E19: =Resurse!C29 | F19: 0.2 | G19: =F3!E9 | H19: =F19*G19 | I19: =Resurse!E29 | J19: =F19*I19 | K19: =Resurse!D29
A20: =F3!A9 | B20: =F3!C9 | C20: U01 | D20: =Resurse!B32 | E20: =Resurse!C32 | F20: 0.03 | G20: =F3!E9 | H20: =F20*G20 | I20: =Resurse!E32 | J20: =F20*I20 | K20: =Resurse!D32
A21: =F3!A9 | B21: =F3!C9 | C21: T01 | D21: =Resurse!B38 | E21: =Resurse!C38 | F21: 1.2 | G21: =F3!E9 | H21: =F21*G21 | I21: =Resurse!E38 | J21: =F21*I21 | K21: =Resurse!D38
A22: =F3!A10 | B22: =F3!C10 | C22: M30 | D22: =Resurse!B11 | E22: =Resurse!C11 | F22: 6 | G22: =F3!E10 | H22: =F22*G22 | I22: =Resurse!E11 | J22: =F22*I22 | K22: =Resurse!D11
A23: =F3!A10 | B23: =F3!C10 | C23: M33 | D23: =Resurse!B14 | E23: =Resurse!C14 | F23: 6 | G23: =F3!E10 | H23: =F23*G23 | I23: =Resurse!E14 | J23: =F23*I23 | K23: =Resurse!D14
A24: =F3!A10 | B24: =F3!C10 | C24: O02 | D24: =Resurse!B28 | E24: =Resurse!C28 | F24: 0.6 | G24: =F3!E10 | H24: =F24*G24 | I24: =Resurse!E28 | J24: =F24*I24 | K24: =Resurse!D28
A25: =F3!A10 | B25: =F3!C10 | C25: O03 | D25: =Resurse!B29 | E25: =Resurse!C29 | F25: 0.3 | G25: =F3!E10 | H25: =F25*G25 | I25: =Resurse!E29 | J25: =F25*I25 | K25: =Resurse!D29
A26: =F3!A10 | B26: =F3!C10 | C26: T01 | D26: =Resurse!B38 | E26: =Resurse!C38 | F26: 0.5 | G26: =F3!E10 | H26: =F26*G26 | I26: =Resurse!E38 | J26: =F26*I26 | K26: =Resurse!D38
A27: =F3!A11 | B27: =F3!C11 | C27: M34 | D27: =Resurse!B15 | E27: =Resurse!C15 | F27: 0.38 | G27: =F3!E11 | H27: =F27*G27 | I27: =Resurse!E15 | J27: =F27*I27 | K27: =Resurse!D15
A28: =F3!A11 | B28: =F3!C11 | C28: M35 | D28: =Resurse!B16 | E28: =Resurse!C16 | F28: 1.6 | G28: =F3!E11 | H28: =F28*G28 | I28: =Resurse!E16 | J28: =F28*I28 | K28: =Resurse!D16
A29: =F3!A11 | B29: =F3!C11 | C29: M36 | D29: =Resurse!B17 | E29: =Resurse!C17 | F29: 0.06 | G29: =F3!E11 | H29: =F29*G29 | I29: =Resurse!E17 | J29: =F29*I29 | K29: =Resurse!D17
A30: =F3!A11 | B30: =F3!C11 | C30: M37 | D30: =Resurse!B18 | E30: =Resurse!C18 | F30: 0.15 | G30: =F3!E11 | H30: =F30*G30 | I30: =Resurse!E18 | J30: =F30*I30 | K30: =Resurse!D18
A31: =F3!A11 | B31: =F3!C11 | C31: O02 | D31: =Resurse!B28 | E31: =Resurse!C28 | F31: 1.1 | G31: =F3!E11 | H31: =F31*G31 | I31: =Resurse!E28 | J31: =F31*I31 | K31: =Resurse!D28
A32: =F3!A11 | B32: =F3!C11 | C32: O03 | D32: =Resurse!B29 | E32: =Resurse!C29 | F32: 0.2 | G32: =F3!E11 | H32: =F32*G32 | I32: =Resurse!E29 | J32: =F32*I32 | K32: =Resurse!D29
A33: =F3!A11 | B33: =F3!C11 | C33: U07 | D33: =Resurse!B37 | E33: =Resurse!C37 | F33: 0.3 | G33: =F3!E11 | H33: =F33*G33 | I33: =Resurse!E37 | J33: =F33*I33 | K33: =Resurse!D37
A34: =F3!A12 | B34: =F3!C12 | C34: M38 | D34: =Resurse!B19 | E34: =Resurse!C19 | F34: 1 | G34: =F3!E12 | H34: =F34*G34 | I34: =Resurse!E19 | J34: =F34*I34 | K34: =Resurse!D19
A35: =F3!A12 | B35: =F3!C12 | C35: M39 | D35: =Resurse!B20 | E35: =Resurse!C20 | F35: 2 | G35: =F3!E12 | H35: =F35*G35 | I35: =Resurse!E20 | J35: =F35*I35 | K35: =Resurse!D20
A36: =F3!A12 | B36: =F3!C12 | C36: O02 | D36: =Resurse!B28 | E36: =Resurse!C28 | F36: 0.45 | G36: =F3!E12 | H36: =F36*G36 | I36: =Resurse!E28 | J36: =F36*I36 | K36: =Resurse!D28
A37: =F3!A12 | B37: =F3!C12 | C37: U02 | D37: =Resurse!B33 | E37: =Resurse!C33 | F37: 0.1 | G37: =F3!E12 | H37: =F37*G37 | I37: =Resurse!E33 | J37: =F37*I37 | K37: =Resurse!D33
A38: =F3!A13 | B38: =F3!C13 | C38: M40 | D38: =Resurse!B21 | E38: =Resurse!C21 | F38: 1.1 | G38: =F3!E13 | H38: =F38*G38 | I38: =Resurse!E21 | J38: =F38*I38 | K38: =Resurse!D21
A39: =F3!A13 | B39: =F3!C13 | C39: M41 | D39: =Resurse!B22 | E39: =Resurse!C22 | F39: 2 | G39: =F3!E13 | H39: =F39*G39 | I39: =Resurse!E22 | J39: =F39*I39 | K39: =Resurse!D22
A40: =F3!A13 | B40: =F3!C13 | C40: O02 | D40: =Resurse!B28 | E40: =Resurse!C28 | F40: 0.15 | G40: =F3!E13 | H40: =F40*G40 | I40: =Resurse!E28 | J40: =F40*I40 | K40: =Resurse!D28
A41: =F3!A14 | B41: =F3!C14 | C41: M42 | D41: =Resurse!B23 | E41: =Resurse!C23 | F41: 1.1 | G41: =F3!E14 | H41: =F41*G41 | I41: =Resurse!E23 | J41: =F41*I41 | K41: =Resurse!D23
...

Sheet C6
A1: C6 – Lista consumurilor de resurse materiale
A2: Obiectiv: Lucrări de reparații acoperiș pav. C4, cazarma 3589 București – Beneficiar: INCDMM „Cantacuzino”
A3: Ofertant: BILZI STEEL PROFILE S.R.L., CUI 39666285, J10/757/2018, Buzău
A4: Valori în lei, fără TVA
A6: Nr. | B6: Denumirea resursei | C6: UM | D6: Cantitate totală | E6: Preț unitar (lei) | F6: Valoare (lei, fără TVA)
A7: 1 | B7: =Resurse!B7 | C7: =Resurse!C7 | D7: =SUMIFS(Analiza!$H$7:$H$52,Analiza!$C$7:$C$52,Resurse!$A$7) | E7: =Resurse!E7 | F7: =ROUND(D7*E7,2)
A8: 2 | B8: =Resurse!B8 | C8: =Resurse!C8 | D8: =SUMIFS(Analiza!$H$7:$H$52,Analiza!$C$7:$C$52,Resurse!$A$8) | E8: =Resurse!E8 | F8: =ROUND(D8*E8,2)
A9: 3 | B9: =Resurse!B9 | C9: =Resurse!C9 | D9: =SUMIFS(Analiza!$H$7:$H$52,Analiza!$C$7:$C$52,Resurse!$A$9) | E9: =Resurse!E9 | F9: =ROUND(D9*E9,2)
A10: 4 | B10: =Resurse!B10 | C10: =Resurse!C10 | D10: =SUMIFS(Analiza!$H$7:$H$52,Analiza!$C$7:$C$52,Resurse!$A$10) | E10: =Resurse!E10 | F10: =ROUND(D10*E10,2)
A11: 5 | B11: =Resurse!B11 | C11: =Resurse!C11 | D11: =SUMIFS(Analiza!$H$7:$H$52,Analiza!$C$7:$C$52,Resurse!$A$11) | E11: =Resurse!E11 | F11: =ROUND(D11*E11,2)
A12: 6 | B12: =Resurse!B12 | C12: =Resurse!C12 | D12: =SUMIFS(Analiza!$H$7:$H$52,Analiza!$C$7:$C$52,Resurse!$A$12) | E12: =Resurse!E12 | F12: =ROUND(D12*E12,2)
A13: 7 | B13: =Resurse!B13 | C13: =Resurse!C13 | D13: =SUMIFS(Analiza!$H$7:$H$52,Analiza!$C$7:$C$52,Resurse!$A$13) | E13: =Resurse!E13 | F13: =ROUND(D13*E13,2)
A14: 8 | B14: =Resurse!B14 | C14: =Resurse!C14 | D14: =SUMIFS(Analiza!$H$7:$H$52,Analiza!$C$7:$C$52,Resurse!$A$14) | E14: =Resurse!E14 | F14: =ROUND(D14*E14,2)
A15: 9 | B15: =Resurse!B15 | C15: =Resurse!C15 | D15: =SUMIFS(Analiza!$H$7:$H$52,Analiza!$C$7:$C$52,Resurse!$A$15) | E15: =Resurse!E15 | F15: =ROUND(D15*E15,2)
A16: 10 | B16: =Resurse!B16 | C16: =Resurse!C16 | D16: =SUMIFS(Analiza!$H$7:$H$52,Analiza!$C$7:$C$52,Resurse!$A$16) | E16: =Resurse!E16 | F16: =ROUND(D16*E16,2)
A17: 11 | B17: =Resurse!B17 | C17: =Resurse!C17 | D17: =SUMIFS(Analiza!$H$7:$H$52,Analiza!$C$7:$C$52,Resurse!$A$17) | E17: =Resurse!E17 | F17: =ROUND(D17*E17,2)
A18: 12 | B18: =Resurse!B18 | C18: =Resurse!C18 | D18: =SUMIFS(Analiza!$H$7:$H$52,Analiza!$C$7:$C$52,Resurse!$A$18) | E18: =Resurse!E18 | F18: =ROUND(D18*E18,2)
A19: 13 | B19: =Resurse!B19 | C19: =Resurse!C19 | D19: =SUMIFS(Analiza!$H$7:$H$52,Analiza!$C$7:$C$52,Resurse!$A$19) | E19: =Resurse!E19 | F19: =ROUND(D19*E19,2)
A20: 14 | B20: =Resurse!B20 | C20: =Resurse!C20 | D20: =SUMIFS(Analiza!$H$7:$H$52,Analiza!$C$7:$C$52,Resurse!$A$20) | E20: =Resurse!E20 | F20: =ROUND(D20*E20,2)
A21: 15 | B21: =Resurse!B21 | C21: =Resurse!C21 | D21: =SUMIFS(Analiza!$H$7:$H$52,Analiza!$C$7:$C$52,Resurse!$A$21) | E21: =Resurse!E21 | F21: =ROUND(D21*E21,2)
A22: 16 | B22: =Resurse!B22 | C22: =Resurse!C22 | D22: =SUMIFS(Analiza!$H$7:$H$52,Analiza!$C$7:$C$52,Resurse!$A$22) | E22: =Resurse!E22 | F22: =ROUND(D22*E22,2)
A23: 17 | B23: =Resurse!B23 | C23: =Resurse!C23 | D23: =SUMIFS(Analiza!$H$7:$H$52,Analiza!$C$7:$C$52,Resurse!$A$23) | E23: =Resurse!E23 | F23: =ROUND(D23*E23,2)
A24: 18 | B24: =Resurse!B24 | C24: =Resurse!C24 | D24: =SUMIFS(Analiza!$H$7:$H$52,Analiza!$C$7:$C$52,Resurse!$A$24) | E24: =Resurse!E24 | F24: =ROUND(D24*E24,2)
A25: 19 | B25: =Resurse!B25 | C25: =Resurse!C25 | D25: =SUMIFS(Analiza!$H$7:$H$52,Analiza!$C$7:$C$52,Resurse!$A$25) | E25: =Resurse!E25 | F25: =ROUND(D25*E25,2)
A26: 20 | B26: =Resurse!B26 | C26: =Resurse!C26 | D26: =SUMIFS(Analiza!$H$7:$H$52,Analiza!$C$7:$C$52,Resurse!$A$26) | E26: =Resurse!E26 | F26: =ROUND(D26*E26,2)
B27: TOTAL | F27: =SUM(F7:F26)
B28: Verificare: diferență față de F3 (rotunjiri, trebuie ≈ 0) | F28: =ROUND(F27-F3!J19,0)
B30: OFERTANT,
B31: BILZI STEEL PROFILE S.R.L.
B32: Șerban Marius – administrator
B33: Semnătura și ștampila

Sheet C7
A1: C7 – Lista consumurilor cu mâna de lucru
A2: Obiectiv: Lucrări de reparații acoperiș pav. C4, cazarma 3589 București – Beneficiar: INCDMM „Cantacuzino”
A3: Ofertant: BILZI STEEL PROFILE S.R.L., CUI 39666285, J10/757/2018, Buzău
A4: Valori în lei, fără TVA
A6: Nr. | B6: Denumirea resursei | C6: UM | D6: Total ore-om | E6: Tarif orar (lei) | F6: Valoare (lei, fără TVA)
A7: 1 | B7: =Resurse!B27 | C7: =Resurse!C27 | D7: =SUMIFS(Analiza!$H$7:$H$52,Analiza!$C$7:$C$52,Resurse!$A$27) | E7: =Resurse!E27 | F7: =ROUND(D7*E7,2)
A8: 2 | B8: =Resurse!B28 | C8: =Resurse!C28 | D8: =SUMIFS(Analiza!$H$7:$H$52,Analiza!$C$7:$C$52,Resurse!$A$28) | E8: =Resurse!E28 | F8: =ROUND(D8*E8,2)
A9: 3 | B9: =Resurse!B29 | C9: =Resurse!C29 | D9: =SUMIFS(Analiza!$H$7:$H$52,Analiza!$C$7:$C$52,Resurse!$A$29) | E9: =Resurse!E29 | F9: =ROUND(D9*E9,2)
A10: 4 | B10: =Resurse!B30 | C10: =Resurse!C30 | D10: =SUMIFS(Analiza!$H$7:$H$52,Analiza!$C$7:$C$52,Resurse!$A$30) | E10: =Resurse!E30 | F10: =ROUND(D10*E10,2)
A11: 5 | B11: =Resurse!B31 | C11: =Resurse!C31 | D11: =SUMIFS(Analiza!$H$7:$H$52,Analiza!$C$7:$C$52,Resurse!$A$31) | E11: =Resurse!E31 | F11: =ROUND(D11*E11,2)
B12: TOTAL | F12: =SUM(F7:F11)
B13: Verificare: diferență față de F3 (rotunjiri, trebuie ≈ 0) | F13: =ROUND(F12-F3!K19,0)
B15: OFERTANT,
B16: BILZI STEEL PROFILE S.R.L.
B17: Șerban Marius – administrator
B18: Semnătura și ștampila

Sheet C8
A1: C8 – Lista consumurilor de ore de funcționare a utilajelor de construcții
A2: Obiectiv: Lucrări de reparații acoperiș pav. C4, cazarma 3589 București – Beneficiar: INCDMM „Cantacuzino”
A3: Ofertant: BILZI STEEL PROFILE S.R.L., CUI 39666285, J10/757/2018, Buzău
A4: Valori în lei, fără TVA
A6: Nr. | B6: Denumirea resursei | C6: UM | D6: Total ore | E6: Tarif orar (lei) | F6: Valoare (lei, fără TVA)
A7: 1 | B7: =Resurse!B32 | C7: =Resurse!C32 | D7: =SUMIFS(Analiza!$H$7:$H$52,Analiza!$C$7:$C$52,Resurse!$A$32) | E7: =Resurse!E32 | F7: =ROUND(D7*E7,2)
A8: 2 | B8: =Resurse!B33 | C8: =Resurse!C33 | D8: =SUMIFS(Analiza!$H$7:$H$52,Analiza!$C$7:$C$52,Resurse!$A$33) | E8: =Resurse!E33 | F8: =ROUND(D8*E8,2)
A9: 3 | B9: =Resurse!B34 | C9: =Resurse!C34 | D9: =SUMIFS(Analiza!$H$7:$H$52,Analiza!$C$7:$C$52,Resurse!$A$34) | E9: =Resurse!E34 | F9: =ROUND(D9*E9,2)
A10: 4 | B10: =Resurse!B35 | C10: =Resurse!C35 | D10: =SUMIFS(Analiza!$H$7:$H$52,Analiza!$C$7:$C$52,Resurse!$A$35) | E10: =Resurse!E35 | F10: =ROUND(D10*E10,2)
A11: 5 | B11: =Resurse!B36 | C11: =Resurse!C36 | D11: =SUMIFS(Analiza!$H$7:$H$52,Analiza!$C$7:$C$52,Resurse!$A$36) | E11: =Resurse!E36 | F11: =ROUND(D11*E11,2)
A12: 6 | B12: =Resurse!B37 | C12: =Resurse!C37 | D12: =SUMIFS(Analiza!$H$7:$H$52,Analiza!$C$7:$C$52,Resurse!$A$37) | E12: =Resurse!E37 | F12: =ROUND(D12*E12,2)
B13: TOTAL | F13: =SUM(F7:F12)
B14: Verificare: diferență față de F3 (rotunjiri, trebuie ≈ 0) | F14: =ROUND(F13-F3!L19,0)
B16: OFERTANT,
B17: BILZI STEEL PROFILE S.R.L.
B18: Șerban Marius – administrator
B19: Semnătura și ștampila

Sheet C9
A1: C9 – Lista consumurilor privind transporturile
A2: Obiectiv: Lucrări de reparații acoperiș pav. C4, cazarma 3589 București – Beneficiar: INCDMM „Cantacuzino”
A3: Ofertant: BILZI STEEL PROFILE S.R.L., CUI 39666285, J10/757/2018, Buzău
A4: Valori în lei, fără TVA
A6: Nr. | B6: Denumirea resursei | C6: UM | D6: Cantitate | E6: Tarif (lei) | F6: Valoare (lei, fără TVA)
A7: 1 | B7: =Resurse!B38 | C7: =Resurse!C38 | D7: =SUMIFS(Analiza!$H$7:$H$52,Analiza!$C$7:$C$52,Resurse!$A$38) | E7: =Resurse!E38 | F7: =ROUND(D7*E7,2)
A8: 2 | B8: =Resurse!B39 | C8: =Resurse!C39 | D8: =SUMIFS(Analiza!$H$7:$H$52,Analiza!$C$7:$C$52,Resurse!$A$39) | E8: =Resurse!E39 | F8: =ROUND(D8*E8,2)
B9: TOTAL | F9: =SUM(F7:F8)
B10: Verificare: diferență față de F3 (rotunjiri, trebuie ≈ 0) | F10: =ROUND(F9-F3!M19,0)
B12: OFERTANT,
B13: BILZI STEEL PROFILE S.R.L.
B14: Șerban Marius – administrator
B15: Semnătura și ștampila

Sheet Grafic
A1: Graficul de execuție fizic și valoric – 45 zile calendaristice (7 săptămâni)
A2: Obiectiv: Lucrări de reparații acoperiș pav. C4, cazarma 3589 București – Beneficiar: INCDMM „Cantacuzino”
A3: Ofertant: BILZI STEEL PROFILE S.R.L., CUI 39666285, J10/757/2018, Buzău
A4: Valori în lei, fără TVA
A6: Nr. | B6: Categoria de lucrări | C6: Valoare totală | D6: Săpt. 1 % | E6: Săpt. 2 % | F6: Săpt. 3 % | G6: Săpt. 4 % | H6: Săpt. 5 % | I6: Săpt. 6 % | J6: Săpt. 7 % | K6: Verificare % | L6: Săpt. 1 lei | M6: Săpt. 2 lei | N6: Săpt. 3 lei | O6: Săpt. 4 lei | P6: Săpt. 5 lei | Q6: Săpt. 6 lei | R6: Săpt. 7 lei
A7: 1 | B7: Pavilion C4 – antemăsurătoare (Anexa 1) | C7: =F3!N24 | D7: 0.15 | E7: 0.2 | F7: 0.2 | G7: 0.2 | H7: 0.15 | I7: 0.1 | J7: 0 | K7: =SUM(D7:J7) | L7: =ROUND($C7*D7,2) | M7: =ROUND($C7*E7,2) | N7: =ROUND($C7*F7,2) | O7: =ROUND($C7*G7,2) | P7: =ROUND($C7*H7,2) | Q7: =ROUND($C7*I7,2) | R7: =ROUND($C7*J7,2)
B8: TOTAL | C8: =SUM(C7:C7) | L8: =SUM(L7:L7) | M8: =SUM(M7:M7) | N8: =SUM(N7:N7) | O8: =SUM(O7:O7) | P8: =SUM(P7:P7) | Q8: =SUM(Q7:Q7) | R8: =SUM(R7:R7)
B9: Verificare: diferență față de totalul F3 (trebuie ≈ 0) | C9: =ROUND(C8-F3!N24,0)
B11: OFERTANT,
B12: BILZI STEEL PROFILE S.R.L.
B13: Șerban Marius – administrator
B14: Semnătura și ștampila

Sheet Anexa oferta
A1: ANEXA LA FORMULARUL DE OFERTĂ
A2: Titlul contractului: „Lucrări de reparații acoperiș pav. C4, cazarma 3589 București”
A4: Denumire | B4: Valoare lei (fără TVA)
A5: Pavilion C4 – antemăsurătoare (Anexa 1) | B5: =Grafic!C7
A6: TOTAL fără TVA | B6: =F3!N24
A7: TVA 21% | B7: =F3!N25
A8: TOTAL cu TVA | B8: =F3!N26
A10: OFERTANT,
A11: BILZI STEEL PROFILE S.R.L.
A12: Șerban Marius – administrator
A13: Semnătura și ștampila
