Workbook

Sheet Instructiuni
A1: Propunere financiară – Înlocuire acoperiș clădire Parc Dofteana – DSBC 2026 II (ADV1549806)
A3: Termen: 07.10.2026, ora 10:00 –
A4: 1. Foaia Resurse: prețurile resurselor (fără TVA) din baza de prețuri BILZI, cu sursa fiecăruia. Celulele galbene se pot modifica – oferta se recalculează.
A5: 2. Foaia Analiza: consumurile pe unitatea fiecărui articol din F3 (norme uzuale, de verificat).
A6: 3. F3: prețurile unitare pe material / manoperă / utilaj / transport rezultă din Analiza; CAM 2,25% din manoperă, cheltuieli indirecte și profit în celulele galbene.
A7: 4. C6–C9, Grafic și Anexa se completează singure; rândurile „Verificare” trebuie să fie 0.
A8: 5. Valoarea estimată: 252,389.69 lei fără TVA. Oferta peste această valoare este respinsă.
A9: Profit aplicat: 12.0% (cel mai mare pas de 0,5% cu care oferta rămâne la cel mult 97% din valoarea estimată, între 5% și 25%).

Sheet F3
A1: F3 – Lista cu cantitățile de lucrări – deviz ofertă
A2: Obiectiv: Înlocuire acoperiș clădire Parc Dofteana – DSBC 2026 II – Beneficiar: Direcția Silvică Bacău
A3: Ofertant: BILZI STEEL PROFILE S.R.L., CUI 39666285, J10/757/2018, Buzău
A4: Valori în lei, fără TVA
A6: Nr. | B6: Simbol | C6: Denumire articol | D6: UM | E6: Cantitate | F6: PU material | G6: PU manoperă | H6: PU utilaj | I6: PU transport | J6: Valoare material | K6: Valoare manoperă | L6: Valoare utilaj | M6: Valoare transport | N6: Total
C7: 02 Demontări
A8: 1 | B8: DEM001 | C8: Demontare învelitoare țiglă ceramică existentă, cu recuperarea materialului | D8: mp | E8: 600 | F8: =ROUND(SUMIFS(Analiza!$J$7:$J$138,Analiza!$A$7:$A$138,$A8,Analiza!$K$7:$K$138,"Material"),2) | G8: =ROUND(SUMIFS(Analiza!$J$7:$J$138,Analiza!$A$7:$A$138,$A8,Analiza!$K$7:$K$138,"Manopera"),2) | H8: =ROUND(SUMIFS(Analiza!$J$7:$J$138,Analiza!$A$7:$A$138,$A8,Analiza!$K$7:$K$138,"Utilaj"),2) | I8: =ROUND(SUMIFS(Analiza!$J$7:$J$138,Analiza!$A$7:$A$138,$A8,Analiza!$K$7:$K$138,"Transport"),2) | J8: =ROUND($E8*F8,2) | K8: =ROUND($E8*G8,2) | L8: =ROUND($E8*H8,2) | M8: =ROUND($E8*I8,2) | N8: =SUM(J8:M8)
A9: 2 | B9: DEM002 | C9: Demontare sistem pluvial existent (jgheaburi, burlane, cârlige, brățări) | D9: ml | E9: 175.82 | F9: =ROUND(SUMIFS(Analiza!$J$7:$J$138,Analiza!$A$7:$A$138,$A9,Analiza!$K$7:$K$138,"Material"),2) | G9: =ROUND(SUMIFS(Analiza!$J$7:$J$138,Analiza!$A$7:$A$138,$A9,Analiza!$K$7:$K$138,"Manopera"),2) | H9: =ROUND(SUMIFS(Analiza!$J$7:$J$138,Analiza!$A$7:$A$138,$A9,Analiza!$K$7:$K$138,"Utilaj"),2) | I9: =ROUND(SUMIFS(Analiza!$J$7:$J$138,Analiza!$A$7:$A$138,$A9,Analiza!$K$7:$K$138,"Transport"),2) | J9: =ROUND($E9*F9,2) | K9: =ROUND($E9*G9,2) | L9: =ROUND($E9*H9,2) | M9: =ROUND($E9*I9,2) | N9: =SUM(J9:M9)
A10: 3 | B10: DEM003 | C10: Demontare instalație paratrăsnet existentă inclusiv console și elemente de fixare | D10: LS | E10: 1 | F10: =ROUND(SUMIFS(Analiza!$J$7:$J$138,Analiza!$A$7:$A$138,$A10,Analiza!$K$7:$K$138,"Material"),2) | G10: =ROUND(SUMIFS(Analiza!$J$7:$J$138,Analiza!$A$7:$A$138,$A10,Analiza!$K$7:$K$138,"Manopera"),2) | H10: =ROUND(SUMIFS(Analiza!$J$7:$J$138,Analiza!$A$7:$A$138,$A10,Analiza!$K$7:$K$138,"Utilaj"),2) | I10: =ROUND(SUMIFS(Analiza!$J$7:$J$138,Analiza!$A$7:$A$138,$A10,Analiza!$K$7:$K$138,"Transport"),2) | J10: =ROUND($E10*F10,2) | K10: =ROUND($E10*G10,2) | L10: =ROUND($E10*H10,2) | M10: =ROUND($E10*I10,2) | N10: =SUM(J10:M10)
A11: 4 | B11: DEM004 | C11: Demontare șorțuri, capace și elemente metalice aferente coșurilor de fum | D11: buc | E11: 4 | F11: =ROUND(SUMIFS(Analiza!$J$7:$J$138,Analiza!$A$7:$A$138,$A11,Analiza!$K$7:$K$138,"Material"),2) | G11: =ROUND(SUMIFS(Analiza!$J$7:$J$138,Analiza!$A$7:$A$138,$A11,Analiza!$K$7:$K$138,"Manopera"),2) | H11: =ROUND(SUMIFS(Analiza!$J$7:$J$138,Analiza!$A$7:$A$138,$A11,Analiza!$K$7:$K$138,"Utilaj"),2) | I11: =ROUND(SUMIFS(Analiza!$J$7:$J$138,Analiza!$A$7:$A$138,$A11,Analiza!$K$7:$K$138,"Transport"),2) | J11: =ROUND($E11*F11,2) | K11: =ROUND($E11*G11,2) | L11: =ROUND($E11*H11,2) | M11: =ROUND($E11*I11,2) | N11: =SUM(J11:M11)
A12: 5 | B12: DEM005 | C12: Demontare tubulatură ceramică existentă coș fum | D12: ml | E12: 40 | F12: =ROUND(SUMIFS(Analiza!$J$7:$J$138,Analiza!$A$7:$A$138,$A12,Analiza!$K$7:$K$138,"Material"),2) | G12: =ROUND(SUMIFS(Analiza!$J$7:$J$138,Analiza!$A$7:$A$138,$A12,Analiza!$K$7:$K$138,"Manopera"),2) | H12: =ROUND(SUMIFS(Analiza!$J$7:$J$138,Analiza!$A$7:$A$138,$A12,Analiza!$K$7:$K$138,"Utilaj"),2) | I12: =ROUND(SUMIFS(Analiza!$J$7:$J$138,Analiza!$A$7:$A$138,$A12,Analiza!$K$7:$K$138,"Transport"),2) | J12: =ROUND($E12*F12,2) | K12: =ROUND($E12*G12,2) | L12: =ROUND($E12*H12,2) | M12: =ROUND($E12*I12,2) | N12: =SUM(J12:M12)
A13: 6 | B13: DEM006 | C13: Demontare lambriu intrados streașină existent | D13: mp | E13: 155 | F13: =ROUND(SUMIFS(Analiza!$J$7:$J$138,Analiza!$A$7:$A$138,$A13,Analiza!$K$7:$K$138,"Material"),2) | G13: =ROUND(SUMIFS(Analiza!$J$7:$J$138,Analiza!$A$7:$A$138,$A13,Analiza!$K$7:$K$138,"Manopera"),2) | H13: =ROUND(SUMIFS(Analiza!$J$7:$J$138,Analiza!$A$7:$A$138,$A13,Analiza!$K$7:$K$138,"Utilaj"),2) | I13: =ROUND(SUMIFS(Analiza!$J$7:$J$138,Analiza!$A$7:$A$138,$A13,Analiza!$K$7:$K$138,"Transport"),2) | J13: =ROUND($E13*F13,2) | K13: =ROUND($E13*G13,2) | L13: =ROUND($E13*H13,2) | M13: =ROUND($E13*I13,2) | N13: =SUM(J13:M13)
A14: 7 | B14: DEM007 | C14: Demontare elemente lemn degradate (astereală, șipci, contrașipci, pazii) | D14: mp | E14: 600 | F14: =ROUND(SUMIFS(Analiza!$J$7:$J$138,Analiza!$A$7:$A$138,$A14,Analiza!$K$7:$K$138,"Material"),2) | G14: =ROUND(SUMIFS(Analiza!$J$7:$J$138,Analiza!$A$7:$A$138,$A14,Analiza!$K$7:$K$138,"Manopera"),2) | H14: =ROUND(SUMIFS(Analiza!$J$7:$J$138,Analiza!$A$7:$A$138,$A14,Analiza!$K$7:$K$138,"Utilaj"),2) | I14: =ROUND(SUMIFS(Analiza!$J$7:$J$138,Analiza!$A$7:$A$138,$A14,Analiza!$K$7:$K$138,"Transport"),2) | J14: =ROUND($E14*F14,2) | K14: =ROUND($E14*G14,2) | L14: =ROUND($E14*H14,2) | M14: =ROUND($E14*I14,2) | N14: =SUM(J14:M14)
A15: 8 | B15: DEM008 | C15: Demontare firidă electrică și elemente suport existente pentru repoziționare | D15: buc | E15: 1 | F15: =ROUND(SUMIFS(Analiza!$J$7:$J$138,Analiza!$A$7:$A$138,$A15,Analiza!$K$7:$K$138,"Material"),2) | G15: =ROUND(SUMIFS(Analiza!$J$7:$J$138,Analiza!$A$7:$A$138,$A15,Analiza!$K$7:$K$138,"Manopera"),2) | H15: =ROUND(SUMIFS(Analiza!$J$7:$J$138,Analiza!$A$7:$A$138,$A15,Analiza!$K$7:$K$138,"Utilaj"),2) | I15: =ROUND(SUMIFS(Analiza!$J$7:$J$138,Analiza!$A$7:$A$138,$A15,Analiza!$K$7:$K$138,"Transport"),2) | J15: =ROUND($E15*F15,2) | K15: =ROUND($E15*G15,2) | L15: =ROUND($E15*H15,2) | M15: =ROUND($E15*I15,2) | N15: =SUM(J15:M15)
A16: 9 | B16: DEM09 | C16: Transportul manual al materialelor, în spații libere și neaccidentate, prin purtat direct pe primii 10 m distanță orizontală, cu încărcătura de cel mult 50 kg, la o distanță de cel mult 60 m | D16: t | E16: 19 | F16: =ROUND(SUMIFS(Analiza!$J$7:$J$138,Analiza!$A$7:$A$138,$A16,Analiza!$K$7:$K$138,"Material"),2) | G16: =ROUND(SUMIFS(Analiza!$J$7:$J$138,Analiza!$A$7:$A$138,$A16,Analiza!$K$7:$K$138,"Manopera"),2) | H16: =ROUND(SUMIFS(Analiza!$J$7:$J$138,Analiza!$A$7:$A$138,$A16,Analiza!$K$7:$K$138,"Utilaj"),2) | I16: =ROUND(SUMIFS(Analiza!$J$7:$J$138,Analiza!$A$7:$A$138,$A16,Analiza!$K$7:$K$138,"Transport"),2) | J16: =ROUND($E16*F16,2) | K16: =ROUND($E16*G16,2) | L16: =ROUND($E16*H16,2) | M16: =ROUND($E16*I16,2) | N16: =SUM(J16:M16)
C17: Total 02 Demontări | J17: =SUM(J8:J16) | K17: =SUM(K8:K16) | L17: =SUM(L8:L16) | M17: =SUM(M8:M16) | N17: =SUM(N8:N16)
C19: 03 Reparații suport lemn
A20: 10 | B20: REP001 | C20: Reparații locale căpriori și grinzi lemn existente prin eclisare și completare secțiune în pod | D20: mc | E20: 1 | F20: =ROUND(SUMIFS(Analiza!$J$7:$J$138,Analiza!$A$7:$A$138,$A20,Analiza!$K$7:$K$138,"Material"),2) | G20: =ROUND(SUMIFS(Analiza!$J$7:$J$138,Analiza!$A$7:$A$138,$A20,Analiza!$K$7:$K$138,"Manopera"),2) | H20: =ROUND(SUMIFS(Analiza!$J$7:$J$138,Analiza!$A$7:$A$138,$A20,Analiza!$K$7:$K$138,"Utilaj"),2) | I20: =ROUND(SUMIFS(Analiza!$J$7:$J$138,Analiza!$A$7:$A$138,$A20,Analiza!$K$7:$K$138,"Transport"),2) | J20: =ROUND($E20*F20,2) | K20: =ROUND($E20*G20,2) | L20: =ROUND($E20*H20,2) | M20: =ROUND($E20*I20,2) | N20: =SUM(J20:M20)
A21: 11 | B21: REP002 | C21: Reparații locale lucarne, terasă existentă, elemente decor lemn (include și consolidări structură de lemn) | D21: buc | E21: 4 | F21: =ROUND(SUMIFS(Analiza!$J$7:$J$138,Analiza!$A$7:$A$138,$A21,Analiza!$K$7:$K$138,"Material"),2) | G21: =ROUND(SUMIFS(Analiza!$J$7:$J$138,Analiza!$A$7:$A$138,$A21,Analiza!$K$7:$K$138,"Manopera"),2) | H21: =ROUND(SUMIFS(Analiza!$J$7:$J$138,Analiza!$A$7:$A$138,$A21,Analiza!$K$7:$K$138,"Utilaj"),2) | I21: =ROUND(SUMIFS(Analiza!$J$7:$J$138,Analiza!$A$7:$A$138,$A21,Analiza!$K$7:$K$138,"Transport"),2) | J21: =ROUND($E21*F21,2) | K21: =ROUND($E21*G21,2) | L21: =ROUND($E21*H21,2) | M21: =ROUND($E21*I21,2) | N21: =SUM(J21:M21)
A22: 12 | B22: REP003 | C22: Curățare strat vechi de vopsea de pe elemente lemn prin sablare laser | D22: ora | E22: 200 | F22: =ROUND(SUMIFS(Analiza!$J$7:$J$138,Analiza!$A$7:$A$138,$A22,Analiza!$K$7:$K$138,"Material"),2) | G22: =ROUND(SUMIFS(Analiza!$J$7:$J$138,Analiza!$A$7:$A$138,$A22,Analiza!$K$7:$K$138,"Manopera"),2) | H22: =ROUND(SUMIFS(Analiza!$J$7:$J$138,Analiza!$A$7:$A$138,$A22,Analiza!$K$7:$K$138,"Utilaj"),2) | I22: =ROUND(SUMIFS(Analiza!$J$7:$J$138,Analiza!$A$7:$A$138,$A22,Analiza!$K$7:$K$138,"Transport"),2) | J22: =ROUND($E22*F22,2) | K22: =ROUND($E22*G22,2) | L22: =ROUND($E22*H22,2) | M22: =ROUND($E22*I22,2) | N22: =SUM(J22:M22)
A23: 13 | B23: REP004 | C23: Chituire, tratament de profunzime, impregnare și vopsire lemn exterior vechi după curățare laser | D23: mp | E23: 50 | F23: =ROUND(SUMIFS(Analiza!$J$7:$J$138,Analiza!$A$7:$A$138,$A23,Analiza!$K$7:$K$138,"Material"),2) | G23: =ROUND(SUMIFS(Analiza!$J$7:$J$138,Analiza!$A$7:$A$138,$A23,Analiza!$K$7:$K$138,"Manopera"),2) | H23: =ROUND(SUMIFS(Analiza!$J$7:$J$138,Analiza!$A$7:$A$138,$A23,Analiza!$K$7:$K$138,"Utilaj"),2) | I23: =ROUND(SUMIFS(Analiza!$J$7:$J$138,Analiza!$A$7:$A$138,$A23,Analiza!$K$7:$K$138,"Transport"),2) | J23: =ROUND($E23*F23,2) | K23: =ROUND($E23*G23,2) | L23: =ROUND($E23*H23,2) | M23: =ROUND($E23*I23,2) | N23: =SUM(J23:M23)
C24: Total 03 Reparații suport lemn | J24: =SUM(J20:J23) | K24: =SUM(K20:K23) | L24: =SUM(L20:L23) | M24: =SUM(M20:M23) | N24: =SUM(N20:N23)
C26: 04 Înlocuire învelitoare
A27: 14 | B27: ACS001 | C27: Înlocuire generală astereală existentă din scândură rășinoase de 25 mm | D27: mp | E27: 600 | F27: =ROUND(SUMIFS(Analiza!$J$7:$J$138,Analiza!$A$7:$A$138,$A27,Analiza!$K$7:$K$138,"Material"),2) | G27: =ROUND(SUMIFS(Analiza!$J$7:$J$138,Analiza!$A$7:$A$138,$A27,Analiza!$K$7:$K$138,"Manopera"),2) | H27: =ROUND(SUMIFS(Analiza!$J$7:$J$138,Analiza!$A$7:$A$138,$A27,Analiza!$K$7:$K$138,"Utilaj"),2) | I27: =ROUND(SUMIFS(Analiza!$J$7:$J$138,Analiza!$A$7:$A$138,$A27,Analiza!$K$7:$K$138,"Transport"),2) | J27: =ROUND($E27*F27,2) | K27: =ROUND($E27*G27,2) | L27: =ROUND($E27*H27,2) | M27: =ROUND($E27*I27,2) | N27: =SUM(J27:M27)
A28: 15 | B28: ACS002 | C28: Montaj șipci 50×50 mm și contrașipci rășinoase 30×50 mm | D28: mp | E28: 600 | F28: =ROUND(SUMIFS(Analiza!$J$7:$J$138,Analiza!$A$7:$A$138,$A28,Analiza!$K$7:$K$138,"Material"),2) | G28: =ROUND(SUMIFS(Analiza!$J$7:$J$138,Analiza!$A$7:$A$138,$A28,Analiza!$K$7:$K$138,"Manopera"),2) | H28: =ROUND(SUMIFS(Analiza!$J$7:$J$138,Analiza!$A$7:$A$138,$A28,Analiza!$K$7:$K$138,"Utilaj"),2) | I28: =ROUND(SUMIFS(Analiza!$J$7:$J$138,Analiza!$A$7:$A$138,$A28,Analiza!$K$7:$K$138,"Transport"),2) | J28: =ROUND($E28*F28,2) | K28: =ROUND($E28*G28,2) | L28: =ROUND($E28*H28,2) | M28: =ROUND($E28*I28,2) | N28: =SUM(J28:M28)
A29: 16 | B29: ACS004 | C29: Montaj folie anticondens 120 g/mp | D29: mp | E29: 600 | F29: =ROUND(SUMIFS(Analiza!$J$7:$J$138,Analiza!$A$7:$A$138,$A29,Analiza!$K$7:$K$138,"Material"),2) | G29: =ROUND(SUMIFS(Analiza!$J$7:$J$138,Analiza!$A$7:$A$138,$A29,Analiza!$K$7:$K$138,"Manopera"),2) | H29: =ROUND(SUMIFS(Analiza!$J$7:$J$138,Analiza!$A$7:$A$138,$A29,Analiza!$K$7:$K$138,"Utilaj"),2) | I29: =ROUND(SUMIFS(Analiza!$J$7:$J$138,Analiza!$A$7:$A$138,$A29,Analiza!$K$7:$K$138,"Transport"),2) | J29: =ROUND($E29*F29,2) | K29: =ROUND($E29*G29,2) | L29: =ROUND($E29*H29,2) | M29: =ROUND($E29*I29,2) | N29: =SUM(J29:M29)
A30: 17 | B30: ACS005 | C30: Montaj țiglă ceramică inclusiv accesorii de fixare | D30: mp | E30: 600 | F30: =ROUND(SUMIFS(Analiza!$J$7:$J$138,Analiza!$A$7:$A$138,$A30,Analiza!$K$7:$K$138,"Material"),2) | G30: =ROUND(SUMIFS(Analiza!$J$7:$J$138,Analiza!$A$7:$A$138,$A30,Analiza!$K$7:$K$138,"Manopera"),2) | H30: =ROUND(SUMIFS(Analiza!$J$7:$J$138,Analiza!$A$7:$A$138,$A30,Analiza!$K$7:$K$138,"Utilaj"),2) | I30: =ROUND(SUMIFS(Analiza!$J$7:$J$138,Analiza!$A$7:$A$138,$A30,Analiza!$K$7:$K$138,"Transport"),2) | J30: =ROUND($E30*F30,2) | K30: =ROUND($E30*G30,2) | L30: =ROUND($E30*H30,2) | M30: =ROUND($E30*I30,2) | N30: =SUM(J30:M30)
A31: 18 | B31: ACS006 | C31: Montaj coamă ventilată din țiglă ceramică | D31: ml | E31: 92.18 | F31: =ROUND(SUMIFS(Analiza!$J$7:$J$138,Analiza!$A$7:$A$138,$A31,Analiza!$K$7:$K$138,"Material"),2) | G31: =ROUND(SUMIFS(Analiza!$J$7:$J$138,Analiza!$A$7:$A$138,$A31,Analiza!$K$7:$K$138,"Manopera"),2) | H31: =ROUND(SUMIFS(Analiza!$J$7:$J$138,Analiza!$A$7:$A$138,$A31,Analiza!$K$7:$K$138,"Utilaj"),2) | I31: =ROUND(SUMIFS(Analiza!$J$7:$J$138,Analiza!$A$7:$A$138,$A31,Analiza!$K$7:$K$138,"Transport"),2) | J31: =ROUND($E31*F31,2) | K31: =ROUND($E31*G31,2) | L31: =ROUND($E31*H31,2) | M31: =ROUND($E31*I31,2) | N31: =SUM(J31:M31)
A32: 19 | B32: ACS007 | C32: Montaj dolie din tablă prevopsită | D32: ml | E32: 26.63 | F32: =ROUND(SUMIFS(Analiza!$J$7:$J$138,Analiza!$A$7:$A$138,$A32,Analiza!$K$7:$K$138,"Material"),2) | G32: =ROUND(SUMIFS(Analiza!$J$7:$J$138,Analiza!$A$7:$A$138,$A32,Analiza!$K$7:$K$138,"Manopera"),2) | H32: =ROUND(SUMIFS(Analiza!$J$7:$J$138,Analiza!$A$7:$A$138,$A32,Analiza!$K$7:$K$138,"Utilaj"),2) | I32: =ROUND(SUMIFS(Analiza!$J$7:$J$138,Analiza!$A$7:$A$138,$A32,Analiza!$K$7:$K$138,"Transport"),2) | J32: =ROUND($E32*F32,2) | K32: =ROUND($E32*G32,2) | L32: =ROUND($E32*H32,2) | M32: =ROUND($E32*I32,2) | N32: =SUM(J32:M32)
A33: 20 | B33: ACS008 | C33: Montaj șorț streașină din tablă prevopsită | D33: ml | E33: 110 | F33: =ROUND(SUMIFS(Analiza!$J$7:$J$138,Analiza!$A$7:$A$138,$A33,Analiza!$K$7:$K$138,"Material"),2) | G33: =ROUND(SUMIFS(Analiza!$J$7:$J$138,Analiza!$A$7:$A$138,$A33,Analiza!$K$7:$K$138,"Manopera"),2) | H33: =ROUND(SUMIFS(Analiza!$J$7:$J$138,Analiza!$A$7:$A$138,$A33,Analiza!$K$7:$K$138,"Utilaj"),2) | I33: =ROUND(SUMIFS(Analiza!$J$7:$J$138,Analiza!$A$7:$A$138,$A33,Analiza!$K$7:$K$138,"Transport"),2) | J33: =ROUND($E33*F33,2) | K33: =ROUND($E33*G33,2) | L33: =ROUND($E33*H33,2) | M33: =ROUND($E33*I33,2) | N33: =SUM(J33:M33)
A34: 21 | B34: ACS009 | C34: Montaj șorț fronton din tablă prevopsită | D34: ml | E34: 9.8 | F34: =ROUND(SUMIFS(Analiza!$J$7:$J$138,Analiza!$A$7:$A$138,$A34,Analiza!$K$7:$K$138,"Material"),2) | G34: =ROUND(SUMIFS(Analiza!$J$7:$J$138,Analiza!$A$7:$A$138,$A34,Analiza!$K$7:$K$138,"Manopera"),2) | H34: =ROUND(SUMIFS(Analiza!$J$7:$J$138,Analiza!$A$7:$A$138,$A34,Analiza!$K$7:$K$138,"Utilaj"),2) | I34: =ROUND(SUMIFS(Analiza!$J$7:$J$138,Analiza!$A$7:$A$138,$A34,Analiza!$K$7:$K$138,"Transport"),2) | J34: =ROUND($E34*F34,2) | K34: =ROUND($E34*G34,2) | L34: =ROUND($E34*H34,2) | M34: =ROUND($E34*I34,2) | N34: =SUM(J34:M34)
A35: 22 | B35: ACS010 | C35: Montaj opritori de zăpadă pentru țigla ceramică | D35: ml | E35: 70 | F35: =ROUND(SUMIFS(Analiza!$J$7:$J$138,Analiza!$A$7:$A$138,$A35,Analiza!$K$7:$K$138,"Material"),2) | G35: =ROUND(SUMIFS(Analiza!$J$7:$J$138,Analiza!$A$7:$A$138,$A35,Analiza!$K$7:$K$138,"Manopera"),2) | H35: =ROUND(SUMIFS(Analiza!$J$7:$J$138,Analiza!$A$7:$A$138,$A35,Analiza!$K$7:$K$138,"Utilaj"),2) | I35: =ROUND(SUMIFS(Analiza!$J$7:$J$138,Analiza!$A$7:$A$138,$A35,Analiza!$K$7:$K$138,"Transport"),2) | J35: =ROUND($E35*F35,2) | K35: =ROUND($E35*G35,2) | L35: =ROUND($E35*H35,2) | M35: =ROUND($E35*I35,2) | N35: =SUM(J35:M35)
A36: 23 | B36: ACS012 | C36: Montaj șorț de racord la perete (lucarne) | D36: ml | E36: 25.4 | F36: =ROUND(SUMIFS(Analiza!$J$7:$J$138,Analiza!$A$7:$A$138,$A36,Analiza!$K$7:$K$138,"Material"),2) | G36: =ROUND(SUMIFS(Analiza!$J$7:$J$138,Analiza!$A$7:$A$138,$A36,Analiza!$K$7:$K$138,"Manopera"),2) | H36: =ROUND(SUMIFS(Analiza!$J$7:$J$138,Analiza!$A$7:$A$138,$A36,Analiza!$K$7:$K$138,"Utilaj"),2) | I36: =ROUND(SUMIFS(Analiza!$J$7:$J$138,Analiza!$A$7:$A$138,$A36,Analiza!$K$7:$K$138,"Transport"),2) | J36: =ROUND($E36*F36,2) | K36: =ROUND($E36*G36,2) | L36: =ROUND($E36*H36,2) | M36: =ROUND($E36*I36,2) | N36: =SUM(J36:M36)
C37: Total 04 Înlocuire învelitoare | J37: =SUM(J27:J36) | K37: =SUM(K27:K36) | L37: =SUM(L27:L36) | M37: =SUM(M27:M36) | N37: =SUM(N27:N36)
C39: 05 Montaj intrados streașină, pazii din lemn
A40: 24 | B40: ACS001 | C40: Montaj lambriu lemn – larice termotratat, clasa A | D40: mp | E40: 155 | F40: =ROUND(SUMIFS(Analiza!$J$7:$J$138,Analiza!$A$7:$A$138,$A40,Analiza!$K$7:$K$138,"Material"),2) | G40: =ROUND(SUMIFS(Analiza!$J$7:$J$138,Analiza!$A$7:$A$138,$A40,Analiza!$K$7:$K$138,"Manopera"),2) | H40: =ROUND(SUMIFS(Analiza!$J$7:$J$138,Analiza!$A$7:$A$138,$A40,Analiza!$K$7:$K$138,"Utilaj"),2) | I40: =ROUND(SUMIFS(Analiza!$J$7:$J$138,Analiza!$A$7:$A$138,$A40,Analiza!$K$7:$K$138,"Transport"),2) | J40: =ROUND($E40*F40,2) | K40: =ROUND($E40*G40,2) | L40: =ROUND($E40*H40,2) | M40: =ROUND($E40*I40,2) | N40: =SUM(J40:M40)
A41: 25 | B41: ACS003 | C41: Montaj pazie lemn – larice termotratat, clasa A | D41: ml | E41: 105 | F41: =ROUND(SUMIFS(Analiza!$J$7:$J$138,Analiza!$A$7:$A$138,$A41,Analiza!$K$7:$K$138,"Material"),2) | G41: =ROUND(SUMIFS(Analiza!$J$7:$J$138,Analiza!$A$7:$A$138,$A41,Analiza!$K$7:$K$138,"Manopera"),2) | H41: =ROUND(SUMIFS(Analiza!$J$7:$J$138,Analiza!$A$7:$A$138,$A41,Analiza!$K$7:$K$138,"Utilaj"),2) | I41: =ROUND(SUMIFS(Analiza!$J$7:$J$138,Analiza!$A$7:$A$138,$A41,Analiza!$K$7:$K$138,"Transport"),2) | J41: =ROUND($E41*F41,2) | K41: =ROUND($E41*G41,2) | L41: =ROUND($E41*H41,2) | M41: =ROUND($E41*I41,2) | N41: =SUM(J41:M41)
C42: Total 05 Montaj intrados streașină, pazii din lemn | J42: =SUM(J40:J41) | K42: =SUM(K40:K41) | L42: =SUM(L40:L41) | M42: =SUM(M40:M41) | N42: =SUM(N40:N41)
C44: 06 Lucrări la instalații electrice și de protecție la trăsnet
A45: 26 | B45: ACS012 | C45: Refacere instalație paratrăsnet acoperiș | D45: LS | E45: 1 | F45: =ROUND(SUMIFS(Analiza!$J$7:$J$138,Analiza!$A$7:$A$138,$A45,Analiza!$K$7:$K$138,"Material"),2) | G45: =ROUND(SUMIFS(Analiza!$J$7:$J$138,Analiza!$A$7:$A$138,$A45,Analiza!$K$7:$K$138,"Manopera"),2) | H45: =ROUND(SUMIFS(Analiza!$J$7:$J$138,Analiza!$A$7:$A$138,$A45,Analiza!$K$7:$K$138,"Utilaj"),2) | I45: =ROUND(SUMIFS(Analiza!$J$7:$J$138,Analiza!$A$7:$A$138,$A45,Analiza!$K$7:$K$138,"Transport"),2) | J45: =ROUND($E45*F45,2) | K45: =ROUND($E45*G45,2) | L45: =ROUND($E45*H45,2) | M45: =ROUND($E45*I45,2) | N45: =SUM(J45:M45)
...

Sheet Resurse
A1: Prețuri resurse (fără TVA)
A2: Obiectiv: Înlocuire acoperiș clădire Parc Dofteana – DSBC 2026 II – Beneficiar: Direcția Silvică Bacău
A3: Ofertant: BILZI STEEL PROFILE S.R.L., CUI 39666285, J10/757/2018, Buzău
A4: Valori în lei, fără TVA
A6: Cod | B6: Denumire resursă | C6: UM | D6: Categorie | E6: Preț unitar (lei) | F6: Sursa prețului
A7: M01 | B7: Cherestea rășinoase (grinzi, căpriori) pentru reparații | C7: mc | D7: Material | E7: 1500 | F7: Estimare (Onești) – de verificat
A8: M02 | B8: Scândură rășinoase 25 mm pentru astereală, tratată | C8: mc | D8: Material | E8: 990 | F8: Depozite cherestea Chitila 02.10.2026: 1.150–1.200 lei/mc (presupus cu TVA) → ~990 lei/mc fără TVA
A9: M03 | B9: Șipci 50×50 și contrașipci 30×50 rășinoase, tratate | C9: mc | D9: Material | E9: 1150 | F9: Depozite cherestea 02.10.2026: șipcă 50×50 2,69–3,10 lei/ml, contrașipcă 1,03–1,55 lei/ml → ~1.150 lei/mc
A10: M04 | B10: Scoabe, cuie și buloane pentru șarpantă | C10: kg | D10: Material | E10: 11 | F10: Estimare (Onești) – de verificat
A11: M05 | B11: Cuie pentru astereală / șipci | C11: kg | D11: Material | E11: 9 | F11: Estimare (Onești) – de verificat
A12: M06 | B12: Soluție fungicidă / insecticidă pentru lemn | C12: l | D12: Material | E12: 14 | F12: Estimare – de verificat
A13: M08 | B13: Folie anticondens min. 120 g/mp | C13: mp | D13: Material | E13: 4.18 | F13: Listă Bilka / Dedeman 02.10.2026: folie anticondens 120–150 g/mp, rolă 75 mp
A14: M09 | B14: Șuruburi autoforante cu garnitură / nituri | C14: buc | D14: Material | E14: 0.25 | F14: Estimare (Onești) – de verificat
A15: M10 | B15: Țiglă ceramică Creaton Balance / Melodie angobată roșu cupru (sau echivalent), inclusiv piese | C15: mp | D15: Material | E15: 66 | F15: Dedeman 02.10.2026: Creaton Balance roșu cupru angoba 7,21 lei/buc fără TVA × 8,7 buc/mp = 62,70 lei/mp + 5% piese speciale
A16: M11 | B16: Cleme de prindere țiglă ceramică | C16: buc | D16: Material | E16: 0.9 | F16: Estimare – de verificat
A17: M12 | B17: Coamă ceramică Creaton (2,5 buc/ml) | C17: ml | D17: Material | E17: 102.15 | F17: Dedeman 02.10.2026: coamă ceramică Creaton PF roșu angoba 40,86 lei/buc × 2,5 buc/ml
A18: M13 | B18: Bandă de coamă ventilată și suport de șipcă coamă | C18: ml | D18: Material | E18: 27.95 | F18: Dedeman 02.10.2026: bandă coamă ventilată Bramac UniRoll 25,95 lei/ml + suport șipcă coamă
... A62: T02 | B62: Container moloz 7 mc (închiriere, transport și eliminare) | C62: buc | D62: Transport | E62: 1800 | F62: Reciclero 2.281 lei (7 zile, cu tratarea deșeurilor) / Moloz24 de la 400 lei – medie rotunjită

Sheet Analiza
A1: Analiza de preț pe articole – consumuri de resurse pe unitatea de măsură a articolului
A2: Obiectiv: Înlocuire acoperiș clădire Parc Dofteana – DSBC 2026 II – Beneficiar: Direcția Silvică Bacău
A3: Ofertant: BILZI STEEL PROFILE S.R.L., CUI 39666285, J10/757/2018, Buzău
A4: Valori în lei, fără TVA
A6: Nr. art. | B6: Articol | C6: Cod resursă | D6: Resursă | E6: UM | F6: Consum / UM articol | G6: Cantitate articol | H6: Consum total | I6: Preț unitar resursă (lei) | J6: Valoare / UM articol | K6: Categorie | L6: Observații
A7: =F3!A8 | B7: =F3!C8 | C7: O02 | D7: =Resurse!B53 | E7: =Resurse!C53 | F7: 0.08329 | G7: =F3!E8 | H7: =F7*G7 | I7: =Resurse!E53 | J7: =F7*I7 | K7: =Resurse!D53
A8: =F3!A8 | B8: =F3!C8 | C8: O03 | D8: =Resurse!B54 | E8: =Resurse!C54 | F8: 0.22437 | G8: =F3!E8 | H8: =F8*G8 | I8: =Resurse!E54 | J8: =F8*I8 | K8: =Resurse!D54
A9: =F3!A9 | B9: =F3!C9 | C9: O02 | D9: =Resurse!B53 | E9: =Resurse!C53 | F9: 0.04997 | G9: =F3!E9 | H9: =F9*G9 | I9: =Resurse!E53 | J9: =F9*I9 | K9: =Resurse!D53
A10: =F3!A9 | B10: =F3!C9 | C10: O03 | D10: =Resurse!B54 | E10: =Resurse!C54 | F10: 0.06411 | G10: =F3!E9 | H10: =F10*G10 | I10: =Resurse!E54 | J10: =F10*I10 | K10: =Resurse!D54
A11: =F3!A10 | B11: =F3!C10 | C11: O05 | D11: =Resurse!B56 | E11: =Resurse!C56 | F11: 3.31034 | G11: =F3!E10 | H11: =F11*G11 | I11: =Resurse!E56 | J11: =F11*I11 | K11: =Resurse!D56
A12: =F3!A10 | B12: =F3!C10 | C12: O03 | D12: =Resurse!B54 | E12: =Resurse!C54 | F12: 3.84638 | G12: =F3!E10 | H12: =F12*G12 | I12: =Resurse!E54 | J12: =F12*I12 | K12: =Resurse!D54
A13: =F3!A11 | B13: =F3!C11 | C13: O02 | D13: =Resurse!B53 | E13: =Resurse!C53 | F13: 0.49971 | G13: =F3!E11 | H13: =F13*G13 | I13: =Resurse!E53 | J13: =F13*I13 | K13: =Resurse!D53
A14: =F3!A11 | B14: =F3!C11 | C14: O03 | D14: =Resurse!B54 | E14: =Resurse!C54 | F14: 0.64106 | G14: =F3!E11 | H14: =F14*G14 | I14: =Resurse!E54 | J14: =F14*I14 | K14: =Resurse!D54
A15: =F3!A12 | B15: =F3!C12 | C15: O04 | D15: =Resurse!B55 | E15: =Resurse!C55 | F15: 0.16551 | G15: =F3!E12 | H15: =F15*G15 | I15: =Resurse!E55 | J15: =F15*I15 | K15: =Resurse!D55
A16: =F3!A12 | B16: =F3!C12 | C16: O03 | D16: =Resurse!B54 | E16: =Resurse!C54 | F16: 0.38464 | G16: =F3!E12 | H16: =F16*G16 | I16: =Resurse!E54 | J16: =F16*I16 | K16: =Resurse!D54
A17: =F3!A13 | B17: =F3!C13 | C17: O01 | D17: =Resurse!B52 | E17: =Resurse!C52 | F17: 0.09994 | G17: =F3!E13 | H17: =F17*G17 | I17: =Resurse!E52 | J17: =F17*I17 | K17: =Resurse!D52
A18: =F3!A13 | B18: =F3!C13 | C18: O03 | D18: =Resurse!B54 | E18: =Resurse!C54 | F18: 0.12821 | G18: =F3!E13 | H18: =F18*G18 | I18: =Resurse!E54 | J18: =F18*I18 | K18: =Resurse!D54
A19: =F3!A14 | B19: =F3!C14 | C19: O01 | D19: =Resurse!B52 | E19: =Resurse!C52 | F19: 0.08329 | G19: =F3!E14 | H19: =F19*G19 | I19: =Resurse!E52 | J19: =F19*I19 | K19: =Resurse!D52
A20: =F3!A14 | B20: =F3!C14 | C20: O03 | D20: =Resurse!B54 | E20: =Resurse!C54 | F20: 0.12821 | G20: =F3!E14 | H20: =F20*G20 | I20: =Resurse!E54 | J20: =F20*I20 | K20: =Resurse!D54
A21: =F3!A14 | B21: =F3!C14 | C21: T02 | D21: =Resurse!B62 | E21: =Resurse!C62 | F21: 0.0045 | G21: =F3!E14 | H21: =F21*G21 | I21: =Resurse!E62 | J21: =F21*I21 | K21: =Resurse!D62
A22: =F3!A15 | B22: =F3!C15 | C22: O05 | D22: =Resurse!B56 | E22: =Resurse!C56 | F22: 1.65517 | G22: =F3!E15 | H22: =F22*G22 | I22: =Resurse!E56 | J22: =F22*I22 | K22: =Resurse!D56
A23: =F3!A16 | B23: =F3!C16 | C23: O03 | D23: =Resurse!B54 | E23: =Resurse!C54 | F23: 1.0257 | G23: =F3!E16 | H23: =F23*G23 | I23: =Resurse!E54 | J23: =F23*I23 | K23: =Resurse!D54
A24: =F3!A20 | B24: =F3!C20 | C24: M01 | D24: =Resurse!B7 | E24: =Resurse!C7 | F24: 1.1 | G24: =F3!E20 | H24: =F24*G24 | I24: =Resurse!E7 | J24: =F24*I24 | K24: =Resurse!D7
A25: =F3!A20 | B25: =F3!C20 | C25: M04 | D25: =Resurse!B10 | E25: =Resurse!C10 | F25: 25 | G25: =F3!E20 | H25: =F25*G25 | I25: =Resurse!E10 | J25: =F25*I25 | K25: =Resurse!D10
A26: =F3!A20 | B26: =F3!C20 | C26: M50 | D26: =Resurse!B34 | E26: =Resurse!C34 | F26: 3 | G26: =F3!E20 | H26: =F26*G26 | I26: =Resurse!E34 | J26: =F26*I26 | K26: =Resurse!D34
A27: =F3!A20 | B27: =F3!C20 | C27: O01 | D27: =Resurse!B52 | E27: =Resurse!C52 | F27: 7.32913 | G27: =F3!E20 | H27: =F27*G27 | I27: =Resurse!E52 | J27: =F27*I27 | K27: =Resurse!D52
A28: =F3!A20 | B28: =F3!C20 | C28: O03 | D28: =Resurse!B54 | E28: =Resurse!C54 | F28: 3.84638 | G28: =F3!E20 | H28: =F28*G28 | I28: =Resurse!E54 | J28: =F28*I28 | K28: =Resurse!D54
A29: =F3!A20 | B29: =F3!C20 | C29: U01 | D29: =Resurse!B58 | E29: =Resurse!C58 | F29: 2 | G29: =F3!E20 | H29: =F29*G29 | I29: =Resurse!E58 | J29: =F29*I29 | K29: =Resurse!D58
A30: =F3!A21 | B30: =F3!C21 | C30: M01 | D30: =Resurse!B7 | E30: =Resurse!C7 | F30: 0.08 | G30: =F3!E21 | H30: =F30*G30 | I30: =Resurse!E7 | J30: =F30*I30 | K30: =Resurse!D7
A31: =F3!A21 | B31: =F3!C21 | C31: M04 | D31: =Resurse!B10 | E31: =Resurse!C10 | F31: 3 | G31: =F3!E21 | H31: =F31*G31 | I31: =Resurse!E10 | J31: =F31*I31 | K31: =Resurse!D10
A32: =F3!A21 | B32: =F3!C21 | C32: M50 | D32: =Resurse!B34 | E32: =Resurse!C34 | F32: 1 | G32: =F3!E21 | H32: =F32*G32 | I32: =Resurse!E34 | J32: =F32*I32 | K32: =Resurse!D34
A33: =F3!A21 | B33: =F3!C21 | C33: M51 | D33: =Resurse!B35 | E33: =Resurse!C35 | F33: 1 | G33: =F3!E21 | H33: =F33*G33 | I33: =Resurse!E35 | J33: =F33*I33 | K33: =Resurse!D35
A34: =F3!A21 | B34: =F3!C21 | C34: O01 | D34: =Resurse!B52 | E34: =Resurse!C52 | F34: 3.99771 | G34: =F3!E21 | H34: =F34*G34 | I34: =Resurse!E52 | J34: =F34*I34 | K34: =Resurse!D52
A35: =F3!A21 | B35: =F3!C21 | C35: O03 | D35: =Resurse!B54 | E35: =Resurse!C54 | F35: 1.92319 | G35: =F3!E21 | H35: =F35*G35 | I35: =Resurse!E54 | J35: =F35*I35 | K35: =Resurse!D54
A36: =F3!A21 | B36: =F3!C21 | C36: U01 | D36: =Resurse!B58 | E36: =Resurse!C58 | F36: 1 | G36: =F3!E21 | H36: =F36*G36 | I36: =Resurse!E58 | J36: =F36*I36 | K36: =Resurse!D58
A37: =F3!A22 | B37: =F3!C22 | C37: U03 | D37: =Resurse!B60 | E37: =Resurse!C60 | F37: 0.18 | G37: =F3!E22 | H37: =F37*G37 | I37: =Resurse!E60 | J37: =F37*I37 | K37: =Resurse!D60
A38: =F3!A22 | B38: =F3!C22 | C38: O07 | D38: =Resurse!B57 | E38: =Resurse!C57 | F38: 0.236 | G38: =F3!E22 | H38: =F38*G38 | I38: =Resurse!E57 | J38: =F38*I38 | K38: =Resurse!D57
A39: =F3!A22 | B39: =F3!C22 | C39: M56 | D39: =Resurse!B40 | E39: =Resurse!C40 | F39: 0.01 | G39: =F3!E22 | H39: =F39*G39 | I39: =Resurse!E40 | J39: =F39*I39 | K39: =Resurse!D40
A40: =F3!A23 | B40: =F3!C23 | C40: M52 | D40: =Resurse!B36 | E40: =Resurse!C36 | F40: 0.3 | G40: =F3!E23 | H40: =F40*G40 | I40: =Resurse!E36 | J40: =F40*I40 | K40: =Resurse!D36
A41: =F3!A23 | B41: =F3!C23 | C41: M53 | D41: =Resurse!B37 | E41: =Resurse!C37 | F41: 0.2 | G41: =F3!E23 | H41: =F41*G41 | I41: =Resurse!E37 | J41: =F41*I41 | K41: =Resurse!D37
...

Sheet C6
A1: C6 – Lista consumurilor de resurse materiale
A2: Obiectiv: Înlocuire acoperiș clădire Parc Dofteana – DSBC 2026 II – Beneficiar: Direcția Silvică Bacău
A3: Ofertant: BILZI STEEL PROFILE S.R.L., CUI 39666285, J10/757/2018, Buzău
A4: Valori în lei, fără TVA
A6: Nr. | B6: Denumirea resursei | C6: UM | D6: Cantitate totală | E6: Preț unitar (lei) | F6: Valoare (lei, fără TVA)
A7: 1 | B7: =Resurse!B7 | C7: =Resurse!C7 | D7: =SUMIFS(Analiza!$H$7:$H$138,Analiza!$C$7:$C$138,Resurse!$A$7) | E7: =Resurse!E7 | F7: =ROUND(D7*E7,2)
A8: 2 | B8: =Resurse!B8 | C8: =Resurse!C8 | D8: =SUMIFS(Analiza!$H$7:$H$138,Analiza!$C$7:$C$138,Resurse!$A$8) | E8: =Resurse!E8 | F8: =ROUND(D8*E8,2)
A9: 3 | B9: =Resurse!B9 | C9: =Resurse!C9 | D9: =SUMIFS(Analiza!$H$7:$H$138,Analiza!$C$7:$C$138,Resurse!$A$9) | E9: =Resurse!E9 | F9: =ROUND(D9*E9,2)
A10: 4 | B10: =Resurse!B10 | C10: =Resurse!C10 | D10: =SUMIFS(Analiza!$H$7:$H$138,Analiza!$C$7:$C$138,Resurse!$A$10) | E10: =Resurse!E10 | F10: =ROUND(D10*E10,2)
A11: 5 | B11: =Resurse!B11 | C11: =Resurse!C11 | D11: =SUMIFS(Analiza!$H$7:$H$138,Analiza!$C$7:$C$138,Resurse!$A$11) | E11: =Resurse!E11 | F11: =ROUND(D11*E11,2)
A12: 6 | B12: =Resurse!B12 | C12: =Resurse!C12 | D12: =SUMIFS(Analiza!$H$7:$H$138,Analiza!$C$7:$C$138,Resurse!$A$12) | E12: =Resurse!E12 | F12: =ROUND(D12*E12,2)
A13: 7 | B13: =Resurse!B13 | C13: =Resurse!C13 | D13: =SUMIFS(Analiza!$H$7:$H$138,Analiza!$C$7:$C$138,Resurse!$A$13) | E13: =Resurse!E13 | F13: =ROUND(D13*E13,2)
A14: 8 | B14: =Resurse!B14 | C14: =Resurse!C14 | D14: =SUMIFS(Analiza!$H$7:$H$138,Analiza!$C$7:$C$138,Resurse!$A$14) | E14: =Resurse!E14 | F14: =ROUND(D14*E14,2)
A15: 9 | B15: =Resurse!B15 | C15: =Resurse!C15 | D15: =SUMIFS(Analiza!$H$7:$H$138,Analiza!$C$7:$C$138,Resurse!$A$15) | E15: =Resurse!E15 | F15: =ROUND(D15*E15,2)
A16: 10 | B16: =Resurse!B16 | C16: =Resurse!C16 | D16: =SUMIFS(Analiza!$H$7:$H$138,Analiza!$C$7:$C$138,Resurse!$A$16) | E16: =Resurse!E16 | F16: =ROUND(D16*E16,2)
A17: 11 | B17: =Resurse!B17 | C17: =Resurse!C17 | D17: =SUMIFS(Analiza!$H$7:$H$138,Analiza!$C$7:$C$138,Resurse!$A$17) | E17: =Resurse!E17 | F17: =ROUND(D17*E17,2)
A18: 12 | B18: =Resurse!B18 | C18: =Resurse!C18 | D18: =SUMIFS(Analiza!$H$7:$H$138,Analiza!$C$7:$C$138,Resurse!$A$18) | E18: =Resurse!E18 | F18: =ROUND(D18*E18,2)
A19: 13 | B19: =Resurse!B19 | C19: =Resurse!C19 | D19: =SUMIFS(Analiza!$H$7:$H$138,Analiza!$C$7:$C$138,Resurse!$A$19) | E19: =Resurse!E19 | F19: =ROUND(D19*E19,2)
A20: 14 | B20: =Resurse!B20 | C20: =Resurse!C20 | D20: =SUMIFS(Analiza!$H$7:$H$138,Analiza!$C$7:$C$138,Resurse!$A$20) | E20: =Resurse!E20 | F20: =ROUND(D20*E20,2)
A21: 15 | B21: =Resurse!B21 | C21: =Resurse!C21 | D21: =SUMIFS(Analiza!$H$7:$H$138,Analiza!$C$7:$C$138,Resurse!$A$21) | E21: =Resurse!E21 | F21: =ROUND(D21*E21,2)
A22: 16 | B22: =Resurse!B22 | C22: =Resurse!C22 | D22: =SUMIFS(Analiza!$H$7:$H$138,Analiza!$C$7:$C$138,Resurse!$A$22) | E22: =Resurse!E22 | F22: =ROUND(D22*E22,2)
A23: 17 | B23: =Resurse!B23 | C23: =Resurse!C23 | D23: =SUMIFS(Analiza!$H$7:$H$138,Analiza!$C$7:$C$138,Resurse!$A$23) | E23: =Resurse!E23 | F23: =ROUND(D23*E23,2)
A24: 18 | B24: =Resurse!B24 | C24: =Resurse!C24 | D24: =SUMIFS(Analiza!$H$7:$H$138,Analiza!$C$7:$C$138,Resurse!$A$24) | E24: =Resurse!E24 | F24: =ROUND(D24*E24,2)
A25: 19 | B25: =Resurse!B25 | C25: =Resurse!C25 | D25: =SUMIFS(Analiza!$H$7:$H$138,Analiza!$C$7:$C$138,Resurse!$A$25) | E25: =Resurse!E25 | F25: =ROUND(D25*E25,2)
A26: 20 | B26: =Resurse!B26 | C26: =Resurse!C26 | D26: =SUMIFS(Analiza!$H$7:$H$138,Analiza!$C$7:$C$138,Resurse!$A$26) | E26: =Resurse!E26 | F26: =ROUND(D26*E26,2)
A27: 21 | B27: =Resurse!B27 | C27: =Resurse!C27 | D27: =SUMIFS(Analiza!$H$7:$H$138,Analiza!$C$7:$C$138,Resurse!$A$27) | E27: =Resurse!E27 | F27: =ROUND(D27*E27,2)
A28: 22 | B28: =Resurse!B28 | C28: =Resurse!C28 | D28: =SUMIFS(Analiza!$H$7:$H$138,Analiza!$C$7:$C$138,Resurse!$A$28) | E28: =Resurse!E28 | F28: =ROUND(D28*E28,2)
A29: 23 | B29: =Resurse!B29 | C29: =Resurse!C29 | D29: =SUMIFS(Analiza!$H$7:$H$138,Analiza!$C$7:$C$138,Resurse!$A$29) | E29: =Resurse!E29 | F29: =ROUND(D29*E29,2)
A30: 24 | B30: =Resurse!B30 | C30: =Resurse!C30 | D30: =SUMIFS(Analiza!$H$7:$H$138,Analiza!$C$7:$C$138,Resurse!$A$30) | E30: =Resurse!E30 | F30: =ROUND(D30*E30,2)
A31: 25 | B31: =Resurse!B31 | C31: =Resurse!C31 | D31: =SUMIFS(Analiza!$H$7:$H$138,Analiza!$C$7:$C$138,Resurse!$A$31) | E31: =Resurse!E31 | F31: =ROUND(D31*E31,2)
A32: 26 | B32: =Resurse!B32 | C32: =Resurse!C32 | D32: =SUMIFS(Analiza!$H$7:$H$138,Analiza!$C$7:$C$138,Resurse!$A$32) | E32: =Resurse!E32 | F32: =ROUND(D32*E32,2)
A33: 27 | B33: =Resurse!B33 | C33: =Resurse!C33 | D33: =SUMIFS(Analiza!$H$7:$H$138,Analiza!$C$7:$C$138,Resurse!$A$33) | E33: =Resurse!E33 | F33: =ROUND(D33*E33,2)
A34: 28 | B34: =Resurse!B34 | C34: =Resurse!C34 | D34: =SUMIFS(Analiza!$H$7:$H$138,Analiza!$C$7:$C$138,Resurse!$A$34) | E34: =Resurse!E34 | F34: =ROUND(D34*E34,2)
A35: 29 | B35: =Resurse!B35 | C35: =Resurse!C35 | D35: =SUMIFS(Analiza!$H$7:$H$138,Analiza!$C$7:$C$138,Resurse!$A$35) | E35: =Resurse!E35 | F35: =ROUND(D35*E35,2)
A36: 30 | B36: =Resurse!B36 | C36: =Resurse!C36 | D36: =SUMIFS(Analiza!$H$7:$H$138,Analiza!$C$7:$C$138,Resurse!$A$36) | E36: =Resurse!E36 | F36: =ROUND(D36*E36,2)
A37: 31 | B37: =Resurse!B37 | C37: =Resurse!C37 | D37: =SUMIFS(Analiza!$H$7:$H$138,Analiza!$C$7:$C$138,Resurse!$A$37) | E37: =Resurse!E37 | F37: =ROUND(D37*E37,2)
A38: 32 | B38: =Resurse!B38 | C38: =Resurse!C38 | D38: =SUMIFS(Analiza!$H$7:$H$138,Analiza!$C$7:$C$138,Resurse!$A$38) | E38: =Resurse!E38 | F38: =ROUND(D38*E38,2)
A39: 33 | B39: =Resurse!B39 | C39: =Resurse!C39 | D39: =SUMIFS(Analiza!$H$7:$H$138,Analiza!$C$7:$C$138,Resurse!$A$39) | E39: =Resurse!E39 | F39: =ROUND(D39*E39,2)
A40: 34 | B40: =Resurse!B40 | C40: =Resurse!C40 | D40: =SUMIFS(Analiza!$H$7:$H$138,Analiza!$C$7:$C$138,Resurse!$A$40) | E40: =Resurse!E40 | F40: =ROUND(D40*E40,2)
A41: 35 | B41: =Resurse!B41 | C41: =Resurse!C41 | D41: =SUMIFS(Analiza!$H$7:$H$138,Analiza!$C$7:$C$138,Resurse!$A$41) | E41: =Resurse!E41 | F41: =ROUND(D41*E41,2)
...

Sheet C7
A1: C7 – Lista consumurilor cu mâna de lucru
A2: Obiectiv: Înlocuire acoperiș clădire Parc Dofteana – DSBC 2026 II – Beneficiar: Direcția Silvică Bacău
A3: Ofertant: BILZI STEEL PROFILE S.R.L., CUI 39666285, J10/757/2018, Buzău
A4: Valori în lei, fără TVA
A6: Nr. | B6: Denumirea resursei | C6: UM | D6: Total ore-om | E6: Tarif orar (lei) | F6: Valoare (lei, fără TVA)
A7: 1 | B7: =Resurse!B52 | C7: =Resurse!C52 | D7: =SUMIFS(Analiza!$H$7:$H$138,Analiza!$C$7:$C$138,Resurse!$A$52) | E7: =Resurse!E52 | F7: =ROUND(D7*E7,2)
A8: 2 | B8: =Resurse!B53 | C8: =Resurse!C53 | D8: =SUMIFS(Analiza!$H$7:$H$138,Analiza!$C$7:$C$138,Resurse!$A$53) | E8: =Resurse!E53 | F8: =ROUND(D8*E8,2)
A9: 3 | B9: =Resurse!B54 | C9: =Resurse!C54 | D9: =SUMIFS(Analiza!$H$7:$H$138,Analiza!$C$7:$C$138,Resurse!$A$54) | E9: =Resurse!E54 | F9: =ROUND(D9*E9,2)
A10: 4 | B10: =Resurse!B55 | C10: =Resurse!C55 | D10: =SUMIFS(Analiza!$H$7:$H$138,Analiza!$C$7:$C$138,Resurse!$A$55) | E10: =Resurse!E55 | F10: =ROUND(D10*E10,2)
A11: 5 | B11: =Resurse!B56 | C11: =Resurse!C56 | D11: =SUMIFS(Analiza!$H$7:$H$138,Analiza!$C$7:$C$138,Resurse!$A$56) | E11: =Resurse!E56 | F11: =ROUND(D11*E11,2)
A12: 6 | B12: =Resurse!B57 | C12: =Resurse!C57 | D12: =SUMIFS(Analiza!$H$7:$H$138,Analiza!$C$7:$C$138,Resurse!$A$57) | E12: =Resurse!E57 | F12: =ROUND(D12*E12,2)
B13: TOTAL | F13: =SUM(F7:F12)
B14: Verificare: diferență față de F3 (rotunjiri, trebuie ≈ 0) | F14: =ROUND(F13-F3!K69,0)
B16: OFERTANT,
B17: BILZI STEEL PROFILE S.R.L.
B18: Șerban Marius – administrator
B19: Semnătura și ștampila

Sheet C8
A1: C8 – Lista consumurilor de ore de funcționare a utilajelor de construcții
A2: Obiectiv: Înlocuire acoperiș clădire Parc Dofteana – DSBC 2026 II – Beneficiar: Direcția Silvică Bacău
A3: Ofertant: BILZI STEEL PROFILE S.R.L., CUI 39666285, J10/757/2018, Buzău
A4: Valori în lei, fără TVA
A6: Nr. | B6: Denumirea resursei | C6: UM | D6: Total ore | E6: Tarif orar (lei) | F6: Valoare (lei, fără TVA)
A7: 1 | B7: =Resurse!B58 | C7: =Resurse!C58 | D7: =SUMIFS(Analiza!$H$7:$H$138,Analiza!$C$7:$C$138,Resurse!$A$58) | E7: =Resurse!E58 | F7: =ROUND(D7*E7,2)
A8: 2 | B8: =Resurse!B59 | C8: =Resurse!C59 | D8: =SUMIFS(Analiza!$H$7:$H$138,Analiza!$C$7:$C$138,Resurse!$A$59) | E8: =Resurse!E59 | F8: =ROUND(D8*E8,2)
A9: 3 | B9: =Resurse!B60 | C9: =Resurse!C60 | D9: =SUMIFS(Analiza!$H$7:$H$138,Analiza!$C$7:$C$138,Resurse!$A$60) | E9: =Resurse!E60 | F9: =ROUND(D9*E9,2)
B10: TOTAL | F10: =SUM(F7:F9)
B11: Verificare: diferență față de F3 (rotunjiri, trebuie ≈ 0) | F11: =ROUND(F10-F3!L69,0)
B13: OFERTANT,
B14: BILZI STEEL PROFILE S.R.L.
B15: Șerban Marius – administrator
B16: Semnătura și ștampila

Sheet C9
A1: C9 – Lista consumurilor privind transporturile
A2: Obiectiv: Înlocuire acoperiș clădire Parc Dofteana – DSBC 2026 II – Beneficiar: Direcția Silvică Bacău
A3: Ofertant: BILZI STEEL PROFILE S.R.L., CUI 39666285, J10/757/2018, Buzău
A4: Valori în lei, fără TVA
A6: Nr. | B6: Denumirea resursei | C6: UM | D6: Cantitate | E6: Tarif (lei) | F6: Valoare (lei, fără TVA)
A7: 1 | B7: =Resurse!B61 | C7: =Resurse!C61 | D7: =SUMIFS(Analiza!$H$7:$H$138,Analiza!$C$7:$C$138,Resurse!$A$61) | E7: =Resurse!E61 | F7: =ROUND(D7*E7,2)
A8: 2 | B8: =Resurse!B62 | C8: =Resurse!C62 | D8: =SUMIFS(Analiza!$H$7:$H$138,Analiza!$C$7:$C$138,Resurse!$A$62) | E8: =Resurse!E62 | F8: =ROUND(D8*E8,2)
B9: TOTAL | F9: =SUM(F7:F8)
B10: Verificare: diferență față de F3 (rotunjiri, trebuie ≈ 0) | F10: =ROUND(F9-F3!M69,0)
B12: OFERTANT,
B13: BILZI STEEL PROFILE S.R.L.
B14: Șerban Marius – administrator
B15: Semnătura și ștampila

Sheet Grafic
A1: Graficul de execuție fizic și valoric – 60 zile calendaristice (9 săptămâni)
A2: Obiectiv: Înlocuire acoperiș clădire Parc Dofteana – DSBC 2026 II – Beneficiar: Direcția Silvică Bacău
A3: Ofertant: BILZI STEEL PROFILE S.R.L., CUI 39666285, J10/757/2018, Buzău
A4: Valori în lei, fără TVA
A6: Nr. | B6: Categoria de lucrări | C6: Valoare totală | D6: Săpt. 1 % | E6: Săpt. 2 % | F6: Săpt. 3 % | G6: Săpt. 4 % | H6: Săpt. 5 % | I6: Săpt. 6 % | J6: Săpt. 7 % | K6: Săpt. 8 % | L6: Săpt. 9 % | M6: Verificare % | N6: Săpt. 1 lei | O6: Săpt. 2 lei | P6: Săpt. 3 lei | Q6: Săpt. 4 lei | R6: Săpt. 5 lei | S6: Săpt. 6 lei | T6: Săpt. 7 lei | U6: Săpt. 8 lei | V6: Săpt. 9 lei
A7: 1 | B7: 02 Demontări | C7: =ROUND(F3!N17/F3!N69*F3!N74,2) | D7: 0.4 | E7: 0.4 | F7: 0.2 | G7: 0 | H7: 0 | I7: 0 | J7: 0 | K7: 0 | L7: 0 | M7: =SUM(D7:L7) | N7: =ROUND($C7*D7,2) | O7: =ROUND($C7*E7,2) | P7: =ROUND($C7*F7,2) | Q7: =ROUND($C7*G7,2) | R7: =ROUND($C7*H7,2) | S7: =ROUND($C7*I7,2) | T7: =ROUND($C7*J7,2) | U7: =ROUND($C7*K7,2) | V7: =ROUND($C7*L7,2)
A8: 2 | B8: 03 Reparații suport lemn | C8: =ROUND(F3!N24/F3!N69*F3!N74,2) | D8: 0 | E8: 0.25 | F8: 0.35 | G8: 0.3 | H8: 0.1 | I8: 0 | J8: 0 | K8: 0 | L8: 0 | M8: =SUM(D8:L8) | N8: =ROUND($C8*D8,2) | O8: =ROUND($C8*E8,2) | P8: =ROUND($C8*F8,2) | Q8: =ROUND($C8*G8,2) | R8: =ROUND($C8*H8,2) | S8: =ROUND($C8*I8,2) | T8: =ROUND($C8*J8,2) | U8: =ROUND($C8*K8,2) | V8: =ROUND($C8*L8,2)
A9: 3 | B9: 04 Înlocuire învelitoare | C9: =ROUND(F3!N37/F3!N69*F3!N74,2) | D9: 0 | E9: 0 | F9: 0.15 | G9: 0.2 | H9: 0.2 | I9: 0.2 | J9: 0.15 | K9: 0.1 | L9: 0 | M9: =SUM(D9:L9) | N9: =ROUND($C9*D9,2) | O9: =ROUND($C9*E9,2) | P9: =ROUND($C9*F9,2) | Q9: =ROUND($C9*G9,2) | R9: =ROUND($C9*H9,2) | S9: =ROUND($C9*I9,2) | T9: =ROUND($C9*J9,2) | U9: =ROUND($C9*K9,2) | V9: =ROUND($C9*L9,2)
A10: 4 | B10: 05 Montaj intrados streașină, pazii din lemn | C10: =ROUND(F3!N42/F3!N69*F3!N74,2) | D10: 0 | E10: 0 | F10: 0 | G10: 0 | H10: 0 | I10: 0.3 | J10: 0.4 | K10: 0.3 | L10: 0 | M10: =SUM(D10:L10) | N10: =ROUND($C10*D10,2) | O10: =ROUND($C10*E10,2) | P10: =ROUND($C10*F10,2) | Q10: =ROUND($C10*G10,2) | R10: =ROUND($C10*H10,2) | S10: =ROUND($C10*I10,2) | T10: =ROUND($C10*J10,2) | U10: =ROUND($C10*K10,2) | V10: =ROUND($C10*L10,2)
A11: 5 | B11: 06 Lucrări la instalații electrice și de protecție la trăsnet | C11: =ROUND(F3!N47/F3!N69*F3!N74,2) | D11: 0.2 | E11: 0 | F11: 0 | G11: 0 | H11: 0 | I11: 0 | J11: 0 | K11: 0.4 | L11: 0.4 | M11: =SUM(D11:L11) | N11: =ROUND($C11*D11,2) | O11: =ROUND($C11*E11,2) | P11: =ROUND($C11*F11,2) | Q11: =ROUND($C11*G11,2) | R11: =ROUND($C11*H11,2) | S11: =ROUND($C11*I11,2) | T11: =ROUND($C11*J11,2) | U11: =ROUND($C11*K11,2) | V11: =ROUND($C11*L11,2)
A12: 6 | B12: 07 Tinichigerie și pluvial | C12: =ROUND(F3!N59/F3!N69*F3!N74,2) | D12: 0 | E12: 0 | F12: 0 | G12: 0 | H12: 0 | I12: 0 | J12: 0.4 | K12: 0.4 | L12: 0.2 | M12: =SUM(D12:L12) | N12: =ROUND($C12*D12,2) | O12: =ROUND($C12*E12,2) | P12: =ROUND($C12*F12,2) | Q12: =ROUND($C12*G12,2) | R12: =ROUND($C12*H12,2) | S12: =ROUND($C12*I12,2) | T12: =ROUND($C12*J12,2) | U12: =ROUND($C12*K12,2) | V12: =ROUND($C12*L12,2)
A13: 7 | B13: 08 Coșuri de fum | C13: =F3!N74-SUM(C7:C12) | D13: 0 | E13: 0 | F13: 0.2 | G13: 0.3 | H13: 0.3 | I13: 0.2 | J13: 0 | K13: 0 | L13: 0 | M13: =SUM(D13:L13) | N13: =ROUND($C13*D13,2) | O13: =ROUND($C13*E13,2) | P13: =ROUND($C13*F13,2) | Q13: =ROUND($C13*G13,2) | R13: =ROUND($C13*H13,2) | S13: =ROUND($C13*I13,2) | T13: =ROUND($C13*J13,2) | U13: =ROUND($C13*K13,2) | V13: =ROUND($C13*L13,2)
B14: TOTAL | C14: =SUM(C7:C13) | N14: =SUM(N7:N13) | O14: =SUM(O7:O13) | P14: =SUM(P7:P13) | Q14: =SUM(Q7:Q13) | R14: =SUM(R7:R13) | S14: =SUM(S7:S13) | T14: =SUM(T7:T13) | U14: =SUM(U7:U13) | V14: =SUM(V7:V13)
B15: Verificare: diferență față de totalul F3 (trebuie ≈ 0) | C15: =ROUND(C14-F3!N74,0)
B17: OFERTANT,
B18: BILZI STEEL PROFILE S.R.L.
B19: Șerban Marius – administrator
B20: Semnătura și ștampila

Sheet Anexa oferta
A1: ANEXA LA FORMULARUL DE OFERTĂ
A2: Titlul contractului: „Înlocuire acoperiș clădire Parc Dofteana – DSBC 2026 II”
A4: Denumire | B4: Valoare lei (fără TVA)
A5: 02 Demontări | B5: =Grafic!C7
A6: 03 Reparații suport lemn | B6: =Grafic!C8
A7: 04 Înlocuire învelitoare | B7: =Grafic!C9
A8: 05 Montaj intrados streașină, pazii din lemn | B8: =Grafic!C10
A9: 06 Lucrări la instalații electrice și de protecție la trăsnet | B9: =Grafic!C11
A10: 07 Tinichigerie și pluvial | B10: =Grafic!C12
A11: 08 Coșuri de fum | B11: =Grafic!C13
A12: TOTAL fără TVA | B12: =F3!N74
A13: TVA 21% | B13: =F3!N75
A14: TOTAL cu TVA | B14: =F3!N76
A16: OFERTANT,
A17: BILZI STEEL PROFILE S.R.L.
A18: Șerban Marius – administrator
A19: Semnătura și ștampila
